Workbook

Sheet Sheet1
A1: 序号 | B1: 负责人 | C1: 场地 | D1: 芸苔现金 | E1: 芸苔微信 | F1: 芸苔支付宝 | G1: 芸苔非团购 | H1: 抖音收款 | I1: 抖音手续费 | J1: 美团收款 | K1: 美团手续费 | L1: 乐摇摇收款 | M1: 多金宝现金 | N1: 多金宝非现金 | O1: 汇联非现金 | P1: 汇联现金 | Q1: 汇联手续费 | R1: StarThing非现金 | S1: StarThing现金 | T1: 鲸舰非现金 | U1: 鲸舰现金 | V1: Kpay收款 | W1: Kpay手续费 | X1: 八达通收款 | Y1: 八达通手续费 | Z1: 芸苔远程取币 | AA1: 其他收入 | AB1: 收入汇总 | AC1: 扣除手续费后 | AD1: 基础货款 | AE1: StarThing积分货款 | AF1: 鲸舰积分货款 | AG1: 新系统积分货款 | AH1: 芸苔积分货款 | AI1: 总货款 | AJ1: 货款比% | AK1: 预计收入(万元) | AL1: 预收入完成率 | AM1: 现金 | AN1: 芸苔投币 | AO1: 多金宝投币 | AP1: 乐摇摇投币 | AQ1: StarThing投币 | AR1: 鲸舰投币 | AS1: 投币合计 | AT1: 芸苔出币 | AU1: StarThing出币 | AV1: 鲸舰出币 | AW1: 多金宝出币 | AX1: 出币合计 | AY1: 芸苔出货 | AZ1: 多金宝出货 | BA1: 乐摇摇出货 | BB1: StarThing出货 | BC1: 鲸舰出货 | BD1: 出货合计 | BE1: 鲸舰积分增加 | BF1: 鲸舰积分减少 | BG1: 新系统积分增加 | BH1: 新系统积分减少 | BI1: StarThing积分增加 | BJ1: StarThing积分减少 | BK1: 芸苔积分增加 | BL1: 芸苔积分减少 | BM1: 存货合计 | BN1: 存货比率（存货与出货比） | BO1: 币值（收入与投币比） | BP1: 出货率（投币与出货比）
A2: 1 | B2: 洪奕翔 | C2: 深圳皇庭广场figgyfinds | H2: 32618.9 | I2: 1670.37 | J2: 48559 | K2: 2455.52 | M2: 5344.8 | N2: 146906.83 | AB2: =G2+H2+J2+L2+M2+N2+O2+P2+R2+S2+T2+U2+V2+X2+Z2+AA2 -> 233429.53 | AC2: 228422.19 | AD2: 79099.065 | AE2: 0 | AF2: 0 | AG2: -73754.25 | AH2: 0 | AI2: 5344.815 | AJ2: =(IFERROR(AI2/AB2,0)) -> 0.022896911 | AM2: =D2+M2+P2+S2+U2 -> 5344.8 | AO2: 426866.5 | AS2: 426866.5 | AW2: 510203.5 | AX2: 510203.5 | AZ2: 4691 | BD2: 4691 | BG2: 44235.5 | BH2: 93405 | BM2: 44235.5 | BN2: 9.4298657 | BO2: =IFERROR(AB2/AS2,0) -> 0.54684433 | BP2: 90.996909
A3: 2 | B3: 郑伟峰 | C3: 福州东百中心 | D3: 7351.1 | E3: 22088.75 | F3: 3159.65 | G3: 32599.5 | H3: 66864.6 | I3: 3347.345 | J3: 21847.6 | K3: 1094.35 | L3: 3558.95 | Z3: 0 | AB3: =G3+H3+J3+L3+M3+N3+O3+P3+R3+S3+T3+U3+V3+X3+Z3+AA3 -> 124870.65 | AC3: 120256.11 | AD3: -10299.195 | AE3: 0 | AF3: 0 | AG3: -1413.75 | AH3: 0 | AI3: -11712.945 | AJ3: =(IFERROR(AI3/AB3,0)) -> -0.093800625 | AM3: =D3+M3+P3+S3+U3 -> 7351.1 | AN3: 42703.5 | AP3: 161281 | AS3: 203984.5 | AT3: 169926 | AX3: 169926 | AY3: 103.5 | BA3: 3557 | BD3: 3660.5 | BG3: 4868.5 | BH3: 5811 | BK3: 0 | BL3: 0 | BM3: 4868.5 | BN3: 1.3300096 | BO3: =IFERROR(AB3/AS3,0) -> 0.61215754 | BP3: 55.725857
A4: 3 | B4: 郑伟峰 | C4: 福州苏宁广场 | D4: 90 | E4: 1459.85 | F4: 260 | G4: 1809.85 | H4: 855.45 | I4: 42.75 | J4: 402 | K4: 20.15 | Z4: 0 | AB4: =G4+H4+J4+L4+M4+N4+O4+P4+R4+S4+T4+U4+V4+X4+Z4+AA4 -> 3067.3 | AC4: 2994.0809 | AE4: 0 | AF4: 0 | AG4: 0 | AH4: 0 | AI4: 0 | AJ4: =(IFERROR(AI4/AB4,0)) -> 0 | AM4: =D4+M4+P4+S4+U4 -> 90 | AN4: 5412.5 | AS4: 5412.5 | AT4: 3699.5 | AX4: 3699.5 | AY4: 87.5 | BD4: 87.5 | BK4: 0 | BL4: 0 | BM4: 0 | BN4: 0 | BO4: =IFERROR(AB4/AS4,0) -> 0.5667067 | BP4: 61.857143
A5: 4 | B5: 郑伟峰 | C5: 福州苏宁广场solmo | H5: 46715.8 | I5: 2350.235 | J5: 19334.35 | K5: 1466.94 | M5: 581.35 | N5: 16288.4 | AB5: =G5+H5+J5+L5+M5+N5+O5+P5+R5+S5+T5+U5+V5+X5+Z5+AA5 -> 82919.9 | AC5: 79004.995 | AD5: 35286.1 | AE5: 0 | AF5: 0 | AG5: 3510 | AH5: 0 | AI5: 38796.1 | AJ5: =(IFERROR(AI5/AB5,0)) -> 0.46787442 | AM5: =D5+M5+P5+S5+U5 -> 581.35 | AO5: 113416 | AS5: 113416 | AW5: 467904.5 | AX5: 467904.5 | AZ5: 2387 | BD5: 2387 | BG5: 5463 | BH5: 3123 | BM5: 5463 | BN5: 2.2886468 | BO5: =IFERROR(AB5/AS5,0) -> 0.73111289 | BP5: 47.514034
A6: 5 | B6: 郑伟峰 | C6: 福州X118多径 | D6: 245 | E6: 4697.85 | F6: 524.9 | G6: 5467.75 | H6: 5075.55 | I6: 253.86 | J6: 1437.2 | K6: 72 | L6: 460.85 | Z6: 0 | AB6: =G6+H6+J6+L6+M6+N6+O6+P6+R6+S6+T6+U6+V6+X6+Z6+AA6 -> 12441.35 | AC6: 12081.388 | AD6: 1052 | AE6: 0 | AF6: 0 | AG6: 0 | AH6: 0 | AI6: 1052 | AJ6: =(IFERROR(AI6/AB6,0)) -> 0.08455674 | AM6: =D6+M6+P6+S6+U6 -> 245 | AN6: 17466 | AP6: 3759.5 | AS6: 21225.5 | AT6: 18148.5 | AX6: 18148.5 | AY6: 141 | BA6: 23 | BD6: 164 | BK6: 0 | BL6: 0 | BM6: 0 | BN6: 0 | BO6: =IFERROR(AB6/AS6,0) -> 0.58615109 | BP6: 129.42378
A7: 6 | B7: 郑伟峰 | C7: 东百中心弹珠机 | D7: 53.5 | E7: 3050.35 | F7: 353.35 | G7: 3457.2 | Z7: 0 | AB7: =G7+H7+J7+L7+M7+N7+O7+P7+R7+S7+T7+U7+V7+X7+Z7+AA7 -> 3457.2 | AC7: 3436.7778 | AD7: 40 | AE7: 0 | AF7: 0 | AG7: 2594.25 | AH7: 0 | AI7: 2634.25 | AJ7: =(IFERROR(AI7/AB7,0)) -> 0.76196055 | AM7: =D7+M7+P7+S7+U7 -> 53.5 | AN7: 0 | AS7: 0 | AT7: 381044.5 | AX7: 381044.5 | AY7: 0 | BD7: 0 | BG7: 2329 | BH7: 599.5 | BK7: 0 | BL7: 0 | BM7: 2329 | BO7: =IFERROR(AB7/AS7,0) -> 0
A8: 7 | B8: 方小丹 | C8: 广州悦汇城负一 | D8: 2217.5 | E8: 28043.45 | F8: 5652.75 | G8: 35913.7 | H8: 14.75 | I8: 0.74 | J8: 14355.55 | K8: 719.3 | Z8: -589.6 | AB8: =G8+H8+J8+L8+M8+N8+O8+P8+R8+S8+T8+U8+V8+X8+Z8+AA8 -> 49694.4 | AC8: 48772.183 | AD8: 12587.79 | AE8: 0 | AF8: 0 | AG8: -756.75 | AH8: 0 | AI8: 11831.04 | AJ8: =(IFERROR(AI8/AB8,0)) -> 0.23807592 | AM8: =D8+M8+P8+S8+U8 -> 2217.5 | AN8: 99062 | AS8: 99062 | AT8: 88889.5 | AX8: 88889.5 | AY8: 2640 | BD8: 2640 | BG8: 2319.5 | BH8: 2824 | BK8: 0 | BL8: 0 | BM8: 2319.5 | BN8: 0.87859848 | BO8: =IFERROR(AB8/AS8,0) -> 0.50164947 | BP8: 37.523485
A9: 8 | B9: 方小丹 | C9: 江门台山万达 | D9: 1626 | E9: 14033.8 | F9: 1835.5 | G9: 17495.3 | H9: 10002 | I9: 508.165 | J9: 6036.3 | K9: 302.44 | Z9: -67.925 | AB9: =G9+H9+J9+L9+M9+N9+O9+P9+R9+S9+T9+U9+V9+X9+Z9+AA9 -> 33465.675 | AC9: 32559.854 | AD9: 10588.75 | AE9: 0 | AF9: 0 | AG9: 480 | AH9: 0 | AI9: 11068.75 | AJ9: =(IFERROR(AI9/AB9,0)) -> 0.33074934 | AM9: =D9+M9+P9+S9+U9 -> 1626 | AN9: 62416.5 | AS9: 62416.5 | AT9: 80520.5 | AX9: 80520.5 | AY9: 1845 | BD9: 1845 | BG9: 1657.5 | BH9: 1337.5 | BK9: 0 | BL9: 0 | BM9: 1657.5 | BN9: 0.89837398 | BO9: =IFERROR(AB9/AS9,0) -> 0.53616712 | BP9: 33.830081
A10: 9 | B10: 方小丹 | C10: 广州保利时光里 | D10: 3546.3 | E10: 27647.3 | F10: 3075.95 | G10: 34269.55 | H10: 14166.95 | I10: 710.225 | J10: 8825.4 | K10: 442.25 | Z10: 720.5 | AB10: =G10+H10+J10+L10+M10+N10+O10+P10+R10+S10+T10+U10+V10+X10+Z10+AA10 -> 57982.4 | AC10: 56645.586 | AD10: 16649.55 | AE10: 0 | AF10: 0 | AG10: 0 | AH10: 2414.25 | AI10: 19063.8 | AJ10: =(IFERROR(AI10/AB10,0)) -> 0.32878598 | AM10: =D10+M10+P10+S10+U10 -> 3546.3 | AN10: 97847.5 | AS10: 97847.5 | AT10: 99388 | AX10: 99388 | AY10: 2932 | BD10: 2932 | BK10: 6218.5 | BL10: 4609 | BM10: 6218.5 | BN10: 2.1209072 | BO10: =IFERROR(AB10/AS10,0) -> 0.59257927 | BP10: 33.372271
A11: 10 | B11: 方小丹 | C11: 广州南沙悦方城 | D11: 0 | E11: 0 | F11: 0 | G11: 0 | Z11: 0 | AB11: =G11+H11+J11+L11+M11+N11+O11+P11+R11+S11+T11+U11+V11+X11+Z11+AA11 -> 0 | AC11: 0 | AE11: 0 | AF11: 0 | AG11: -192 | AH11: 0 | AI11: -192 | AJ11: =(IFERROR(AI11/AB11,0)) -> 0 | AM11: =D11+M11+P11+S11+U11 -> 0 | AN11: 0 | AS11: 0 | AT11: 0 | AX11: 0 | AY11: 0 | BD11: 0 | BG11: 20.5 | BH11: 148.5 | BK11: 0 | BL11: 0 | BM11: 20.5 | BO11: =IFERROR(AB11/AS11,0) -> 0
A12: 11 | B12: 方小丹 | C12: 广州南沙悦方城多径 | D12: 0 | E12: 0 | F12: 0 | G12: 0 | Z12: 0 | AB12: =G12+H12+J12+L12+M12+N12+O12+P12+R12+S12+T12+U12+V12+X12+Z12+AA12 -> 0 | AC12: 0 | AE12: 0 | AF12: 0 | AG12: 0 | AH12: 0 | AI12: 0 | AJ12: =(IFERROR(AI12/AB12,0)) -> 0 | AM12: =D12+M12+P12+S12+U12 -> 0 | AN12: 0 | AS12: 0 | AT12: 0 | AX12: 0 | AY12: 0 | BD12: 0 | BK12: 0 | BL12: 0 | BM12: 0 | BO12: =IFERROR(AB12/AS12,0) -> 0
A13: 12 | B13: 方小丹 | C13: 健康港星河(广州星河多径) | D13: 233.5 | E13: 2892.45 | F13: 348.15 | G13: 3474.1 | L13: 44.85 | Z13: 0 | AB13: =G13+H13+J13+L13+M13+N13+O13+P13+R13+S13+T13+U13+V13+X13+Z13+AA13 -> 3518.95 | AC13: 3499.2373 | AE13: 0 | AF13: 0 | AG13: 0 | AH13: 0 | AI13: 0 | AJ13: =(IFERROR(AI13/AB13,0)) -> 0 | AM13: =D13+M13+P13+S13+U13 -> 233.5 | AN13: 2865.5 | AP13: 3333 | AS13: 6198.5 | AT13: 5870.5 | AX13: 5870.5 | AY13: 107 | BA13: 145.5 | BD13: 252.5 | BK13: 0 | BL13: 0 | BM13: 0 | BN13: 0 | BO13: =IFERROR(AB13/AS13,0) -> 0.56770993 | BP13: 24.548515
A14: 13 | B14: 方小丹 | C14: 深圳宝安怀德万象汇solmo | D14: 0 | E14: 0 | F14: 0 | G14: 0 | H14: 8183.6 | I14: 411.21 | J14: 4868.1 | K14: 350.53 | M14: 798 | N14: 12964.6 | Z14: 0 | AA14: 64.23 | AB14: =G14+H14+J14+L14+M14+N14+O14+P14+R14+S14+T14+U14+V14+X14+Z14+AA14 -> 26878.53 | AC14: 26039.002 | AD14: 9869.525 | AE14: 0 | AF14: 0 | AG14: -605.25 | AH14: 0 | AI14: 9264.275 | AJ14: =(IFERROR(AI14/AB14,0)) -> 0.34467194 | AM14: =D14+M14+P14+S14+U14 -> 798 | AN14: 0 | AO14: 60258 | AS14: 60258 | AT14: 0 | AW14: 111309.5 | AX14: 111309.5 | AY14: 0 | AZ14: 2499.5 | BD14: 2499.5 | BG14: 329 | BH14: 732.5 | BK14: 0 | BL14: 0 | BM14: 329 | BN14: 0.13162633 | BO14: =IFERROR(AB14/AS14,0) -> 0.44605745 | BP14: 24.108022
A15: 14 | B15: 方小丹 | C15: 深圳宝安怀德万象汇figgyfinds | H15: 890.15 | I15: 45.28 | L15: 0 | M15: 117.5 | N15: 1775.65 | AA15: 11.23 | AB15: =G15+H15+J15+L15+M15+N15+O15+P15+R15+S15+T15+U15+V15+X15+Z15+AA15 -> 2794.53 | AC15: 2738.5961 | AD15: 446.645 | AE15: 0 | AF15: 0 | AG15: -156.75 | AH15: 0 | AI15: 289.895 | AJ15: =(IFERROR(AI15/AB15,0)) -> 0.10373659 | AM15: =D15+M15+P15+S15+U15 -> 117.5 | AO15: 997.5 | AP15: 13.5 | AS15: 1011 | AW15: 17203 | AX15: 17203 | AZ15: 11.5 | BA15: 0.5 | BD15: 12 | BG15: 0 | BH15: 104.5 | BM15: 0 | BN15: 0 | BO15: =IFERROR(AB15/AS15,0) -> 2.7641246 | BP15: 84.25
A16: 15 | B16: 方小丹 | C16: 深圳龙岗大运天地figgyfinds | H16: 38723.45 | I16: 1943.64 | J16: 20011.2 | K16: 1276.135 | M16: 1463.4 | N16: 20643 | AA16: 411.72 | AB16: =G16+H16+J16+L16+M16+N16+O16+P16+R16+S16+T16+U16+V16+X16+Z16+AA16 -> 81252.77 | AC16: 77909.137 | AD16: 22911.235 | AE16: 0 | AF16: 0 | AG16: -5130 | AH16: 0 | AI16: 17781.235 | AJ16: =(IFERROR(AI16/AB16,0)) -> 0.21883851 | AM16: =D16+M16+P16+S16+U16 -> 1463.4 | AO16: 91854 | AS16: 91854 | AW16: 365546 | AX16: 365546 | AZ16: 2028 | BD16: 2028 | BG16: 6783.5 | BH16: 10203.5 | BM16: 6783.5 | BN16: 3.3449211 | BO16: =IFERROR(AB16/AS16,0) -> 0.88458608 | BP16: 45.292899
A17: 16 | B17: 方小丹 | C17: 深圳海岸城爪物超柿 | H17: 29449.205 | I17: 1486.46 | J17: 54848.35 | K17: 3501.825 | M17: 1908.55 | N17: 68561.2 | AB17: =G17+H17+J17+L17+M17+N17+O17+P17+R17+S17+T17+U17+V17+X17+Z17+AA17 -> 154767.3 | AC17: 149367.65 | AD17: 90509.685 | AE17: 0 | AF17: 0 | AG17: 21251.25 | AH17: 0 | AI17: 111760.93 | AJ17: =(IFERROR(AI17/AB17,0)) -> 0.72212238 | AM17: =D17+M17+P17+S17+U17 -> 1908.55 | AO17: 302312 | AS17: 302312 | AW17: 365424.5 | AX17: 365424.5 | AZ17: 6102 | BD17: 6102 | BG17: 16426.5 | BH17: 2259 | BM17: 16426.5 | BN17: 2.6919862 | BO17: =IFERROR(AB17/AS17,0) -> 0.51194562 | BP17: 49.543101
A18: 17 | B18: 方小丹 | C18: 深圳布吉万象汇figgyfinds | H18: 46630.35 | I18: 2346.89 | J18: 33972.05 | K18: 1509.66 | M18: 2113.2 | N18: 35279.75 | AA18: 500 | AB18: =G18+H18+J18+L18+M18+N18+O18+P18+R18+S18+T18+U18+V18+X18+Z18+AA18 -> 118495.35 | AC18: 114427.12 | AD18: 45770.345 | AE18: 0 | AF18: 0 | AG18: -69 | AH18: 0 | AI18: 45701.345 | AJ18: =(IFERROR(AI18/AB18,0)) -> 0.38568049 | AM18: =D18+M18+P18+S18+U18 -> 2113.2 | AO18: 231439.5 | AS18: 231439.5 | AW18: 250575 | AX18: 250575 | AZ18: 4615 | BD18: 4615 | BG18: 18928.5 | BH18: 18974.5 | BM18: 18928.5 | BN18: 4.1015168 | BO18: =IFERROR(AB18/AS18,0) -> 0.51199277 | BP18: 50.149404
A19: 18 | B19: 方小丹 | C19: 广州花都骏壹万邦广场figgyfinds | H19: 36282.31 | I19: 1824.89 | J19: 38994.4 | K19: 2479.605 | M19: 2082 | N19: 43626.35 | AB19: =G19+H19+J19+L19+M19+N19+O19+P19+R19+S19+T19+U19+V19+X19+Z19+AA19 -> 120985.06 | AC19: 116418.81 | AD19: 41771.655 | AE19: 0 | AF19: 0 | AG19: 1126.5 | AH19: 0 | AI19: 42898.155 | AJ19: =(IFERROR(AI19/AB19,0)) -> 0.35457399 | AM19: =D19+M19+P19+S19+U19 -> 2082 | AO19: 211258 | AS19: 211258 | AW19: 198348 | AX19: 198348 | AZ19: 4307 | BD19: 4307 | BG19: 14741.5 | BH19: 13990.5 | BM19: 14741.5 | BN19: 3.422684 | BO19: =IFERROR(AB19/AS19,0) -> 0.57268866 | BP19: 49.049919
A20: 19 | B20: 方小丹 | C20: 东莞松山湖万象汇figgyfinds | D20: 0 | E20: 0 | F20: 0 | G20: 0 | H20: 66939 | I20: 3368.2 | J20: 32865.9 | K20: 2271.475 | M20: 1069.55 | N20: 29009.5 | Z20: 0 | AA20: 10.88 | AB20: =G20+H20+J20+L20+M20+N20+O20+P20+R20+S20+T20+U20+V20+X20+Z20+AA20 -> 129894.83 | AC20: 124081.1 | AD20: 46664.255 | AE20: 0 | AF20: 0 | AG20: -3476.25 | AH20: 0 | AI20: 43188.005 | AJ20: =(IFERROR(AI20/AB20,0)) -> 0.3324844 | AM20: =D20+M20+P20+S20+U20 -> 1069.55 | AN20: 0 | AO20: 186151 | AS20: 186151 | AT20: 0 | AW20: 533912 | AX20: 533912 | AY20: 0 | AZ20: 4463.5 | BD20: 4463.5 | BG20: 12225.5 | BH20: 14543 | BK20: 0 | BL20: 0 | BM20: 12225.5 | BN20: 2.7389941 | BO20: =IFERROR(AB20/AS20,0) -> 0.69779281 | BP20: 41.705164
A21: 20 | B21: 方小丹 | C21: 福永益田假日 | D21: 524 | E21: 2365.3 | F21: 618.85 | G21: 3508.15 | H21: 1119.45 | I21: 55.98 | J21: 863.05 | K21: 69.805 | L21: 1966.05 | O21: 1732.475 | P21: 151.5 | Q21: 10.625 | Z21: 0 | AB21: =G21+H21+J21+L21+M21+N21+O21+P21+R21+S21+T21+U21+V21+X21+Z21+AA21 -> 9340.675 | AC21: 9174.5638 | AD21: -17658.25 | AE21: 0 | AF21: 0 | AG21: 0 | AH21: 0 | AI21: -17658.25 | AJ21: =(IFERROR(AI21/AB21,0)) -> -1.8904683 | AM21: =D21+M21+P21+S21+U21 -> 675.5 | AN21: 11534.5 | AP21: 2.5 | AS21: 11537 | AT21: 7111 | AX21: 7111 | AY21: 313 | BA21: 0.5 | BD21: 313.5 | BG21: 0 | BH21: 0 | BK21: 0 | BL21: 0 | BM21: 0 | BN21: 0 | BO21: =IFERROR(AB21/AS21,0) -> 0.80962772 | BP21: 36.800638
A22: 21 | B22: 方小丹 | C22: Solmo娃娃市集(摩尔城店) | H22: 3601.6 | I22: 180.855 | J22: 2557.5 | K22: 182.71 | M22: 754 | N22: 6583.2 | AB22: =G22+H22+J22+L22+M22+N22+O22+P22+R22+S22+T22+U22+V22+X22+Z22+AA22 -> 13496.3 | AC22: 13093.236 | AD22: 50 | AE22: 0 | AF22: 0 | AG22: 0 | AH22: 0 | AI22: 50 | AJ22: =(IFERROR(AI22/AB22,0)) -> 0.0037047191 | AM22: =D22+M22+P22+S22+U22 -> 754 | AO22: 0 | AS22: 0 | AW22: 134897.5 | AX22: 134897.5 | AZ22: 0 | BD22: 0 | BM22: 0 | BO22: =IFERROR(AB22/AS22,0) -> 0
A23: 22 | B23: 王青 | C23: 上海宏伊广场 | D23: 5147.35 | E23: 24437.35 | F23: 21668.3 | G23: 51253 | H23: 9923.25 | I23: 501.08 | J23: 8020.45 | K23: 401.8 | Z23: 0 | AB23: =G23+H23+J23+L23+M23+N23+O23+P23+R23+S23+T23+U23+V23+X23+Z23+AA23 -> 69196.7 | AC23: 68017.186 | AE23: 0 | AF23: 0 | AG23: -113.25 | AH23: 0 | AI23: -113.25 | AJ23: =(IFERROR(AI23/AB23,0)) -> -0.0016366387 | AM23: =D23+M23+P23+S23+U23 -> 5147.35 | AN23: 76076.5 | AS23: 76076.5 | AT23: 73204.5 | AX23: 73204.5 | AY23: 2147.5 | BD23: 2147.5 | BG23: 1461 | BH23: 1536.5 | BK23: 0 | BL23: 0 | BM23: 1461 | BN23: 0.68032596 | BO23: =IFERROR(AB23/AS23,0) -> 0.90956734 | BP23: 35.425611
A24: 23 | B24: 王青 | C24: 香港黄埔物超柿 | T24: 146998.8 | U24: 314654.8 | AB24: =G24+H24+J24+L24+M24+N24+O24+P24+R24+S24+T24+U24+V24+X24+Z24+AA24 -> 461653.6 | AC24: 461653.6 | AD24: 190487.38 | AE24: 0 | AF24: 34425.5 | AG24: 0 | AH24: 0 | AI24: 224912.88 | AJ24: =(IFERROR(AI24/AB24,0)) -> 0.48718969 | AM24: =D24+M24+P24+S24+U24 -> 314654.8 | AR24: 607582.5 | AS24: 607582.5 | AV24: 598338.5 | AX24: 598338.5 | BC24: 14943.5 | BD24: 14943.5 | BE24: 74443.5 | BF24: 40018 | BM24: 74443.5 | BN24: 4.9816643 | BO24: =IFERROR(AB24/AS24,0) -> 0.75982044 | BP24: 40.658648
A25: 24 | B25: 王青 | C25: 香港九龙城店 | M25: 400 | N25: 0 | V25: 294.5 | W25: 5.24 | AA25: 14945 | AB25: =G25+H25+J25+L25+M25+N25+O25+P25+R25+S25+T25+U25+V25+X25+Z25+AA25 -> 15639.5 | AC25: 15634.26 | AD25: -9001 | AE25: 0 | AF25: 0 | AG25: 0 | AH25: 0 | AI25: -9001 | AJ25: =(IFERROR(AI25/AB25,0)) -> -0.57552991 | AM25: =D25+M25+P25+S25+U25 -> 400 | AO25: 199.5 | AS25: 199.5 | AW25: 0 | AX25: 0 | AZ25: 3 | BD25: 3 | BM25: 0 | BN25: 0 | BO25: =IFERROR(AB25/AS25,0) -> 78.393484 | BP25: 66.5
A26: 25 | B26: 梁志成 | C26: 香港宝林FF | R26: 111837.5 | S26: 70945 | AB26: =G26+H26+J26+L26+M26+N26+O26+P26+R26+S26+T26+U26+V26+X26+Z26+AA26 -> 182782.5 | AC26: 182782.5 | AD26: 83532.715 | AE26: 16811 | AF26: 0 | AG26: 0 | AH26: 0 | AI26: 100343.71 | AJ26: =(IFERROR(AI26/AB26,0)) -> 0.54897879 | AM26: =D26+M26+P26+S26+U26 -> 70945 | AS26: 0 | AU26: 371008.5 | AX26: 371008.5 | BB26: 5049.5 | BD26: 5049.5 | BI26: 45565.32 | BJ26: 28754.32 | BM26: 45565.32 | BN26: 9.0237291 | BO26: =IFERROR(AB26/AS26,0) -> 0 | BP26: 0
A27: 26 | B27: 梁志成 | C27: 香港将军澳店 | M27: 3568 | N27: 0 | R27: 4885 | S27: 7345 | V27: 18309.5 | W27: 263.65 | X27: 3909.5 | AB27: =G27+H27+J27+L27+M27+N27+O27+P27+R27+S27+T27+U27+V27+X27+Z27+AA27 -> 38017 | AC27: 37753.35 | AD27: 44957.44 | AE27: 0 | AF27: 0 | AG27: 0 | AH27: 0 | AI27: 44957.44 | AJ27: =(IFERROR(AI27/AB27,0)) -> 1.1825615 | AM27: =D27+M27+P27+S27+U27 -> 10913 | AO27: 37247.5 | AS27: 37247.5 | AU27: 0 | AW27: 0 | AX27: 0 | AZ27: 1435 | BB27: 0 | BD27: 1435 | BI27: 0 | BJ27: 0 | BM27: 0 | BN27: 0 | BO27: =IFERROR(AB27/AS27,0) -> 1.0206591 | BP27: 25.956446
A28: 27 | B28: 吴兴涛 | C28: 香港K11 | T28: 38650 | U28: 332049.5 | AB28: =G28+H28+J28+L28+M28+N28+O28+P28+R28+S28+T28+U28+V28+X28+Z28+AA28 -> 370699.5 | AC28: 370699.5 | AD28: 287886.92 | AE28: 0 | AF28: 58234.5 | AG28: 0 | AH28: 0 | AI28: 346121.42 | AJ28: =(IFERROR(AI28/AB28,0)) -> 0.9336981 | AM28: =D28+M28+P28+S28+U28 -> 332049.5 | AR28: 544396 | AS28: 544396 | AV28: 454091 | AX28: 454091 | BC28: 13124 | BD28: 13124 | BE28: 140615.5 | BF28: 82381 | BM28: 140615.5 | BN28: 10.714378 | BO28: =IFERROR(AB28/AS28,0) -> 0.68093722 | BP28: 41.480951
A29: 28 | B29: 文龙 | C29: 香港沙田希尔顿物超柿 | T29: 125841.5 | U29: 63241 | AB29: =G29+H29+J29+L29+M29+N29+O29+P29+R29+S29+T29+U29+V29+X29+Z29+AA29 -> 189082.5 | AC29: 189082.5 | AD29: 117431.43 | AE29: 0 | AF29: -49642 | AG29: 0 | AH29: 0 | AI29: 67789.43 | AJ29: =(IFERROR(AI29/AB29,0)) -> 0.35851774 | AM29: =D29+M29+P29+S29+U29 -> 63241 | AR29: 275411.5 | AS29: 275411.5 | AV29: 260465 | AX29: 260465 | BC29: 5083 | BD29: 5083 | BE29: 60113 | BF29: 109755 | BM29: 60113 | BN29: 11.826284 | BO29: =IFERROR(AB29/AS29,0) -> 0.68654541 | BP29: 54.182864
A30: 29 | B30: 徐丹 | C30: 香港如心物超柿 | R30: 38859 | S30: 29746.5 | AB30: =G30+H30+J30+L30+M30+N30+O30+P30+R30+S30+T30+U30+V30+X30+Z30+AA30 -> 68605.5 | AC30: 68605.5 | AD30: 9377.75 | AE30: 1537.5 | AF30: 0 | AG30: 0 | AH30: 0 | AI30: 10915.25 | AJ30: =(IFERROR(AI30/AB30,0)) -> 0.15910168 | AM30: =D30+M30+P30+S30+U30 -> 29746.5 | AS30: 0 | AU30: 79453 | AX30: 79453 | BB30: 1692.5 | BD30: 1692.5 | BI30: 13304.5 | BJ30: 11767 | BM30: 13304.5 | BN30: 7.8608567 | BO30: =IFERROR(AB30/AS30,0) -> 0 | BP30: 0
A31: 30 | B31: 徐丹 | C31: 香港荃湾FF | T31: 100899.45 | U31: 67393.5 | X31: 106 | AB31: =G31+H31+J31+L31+M31+N31+O31+P31+R31+S31+T31+U31+V31+Z31+AA31 -> 168292.95 | AC31: 168292.95 | AD31: 142508.02 | AE31: 0 | AF31: -23491.5 | AG31: 0 | AH31: 0 | AI31: 119016.52 | AJ31: =(IFERROR(AI31/AB31,0)) -> 0.70719849 | AM31: =D31+M31+P31+S31+U31 -> 67393.5 | AR31: 274303 | AS31: 274303 | AV31: 199626.5 | AX31: 199626.5 | BC31: 9402 | BD31: 9402 | BE31: 112229.5 | BF31: 135721 | BM31: 112229.5 | BN31: 11.936769 | BO31: =IFERROR(AB31/AS31,0) -> 0.61352938 | BP31: 29.174963
A32: 31 | B32: 徐丹 | C32: 香港大学物超柿 | T32: 3268.5 | U32: 8432 | AB32: =G32+H32+J32+L32+M32+N32+O32+P32+R32+S32+T32+U32+V32+X32+Z32+AA32 -> 11700.5 | AC32: 11700.5 | AD32: 17228.275 | AE32: 0 | AF32: -10868 | AG32: 0 | AH32: 0 | AI32: 6360.275 | AJ32: =(IFERROR(AI32/AB32,0)) -> 0.54359002 | AM32: =D32+M32+P32+S32+U32 -> 8432 | AR32: 14412 | AS32: 14412 | AV32: 10715 | AX32: 10715 | BC32: 180.5 | BD32: 180.5 | BE32: 1335.5 | BF32: 12203.5 | BM32: 1335.5 | BN32: 7.398892 | BO32: =IFERROR(AB32/AS32,0) -> 0.81185817 | BP32: 79.844875
A33: 32 | B33: 徐丹 | C33: Figgy Finds娃娃市集(罗湖店) | H33: 31215.45 | I33: 1587.685 | J33: 19749.35 | K33: 1358.915 | M33: 1964.7 | N33: 40365.8 | AB33: =G33+H33+J33+L33+M33+N33+O33+P33+R33+S33+T33+U33+V33+X33+Z33+AA33 -> 93295.3 | AC33: 90106.505 | AD33: 11255.5 | AE33: 0 | AF33: 0 | AG33: 11943 | AH33: 0 | AI33: 23198.5 | AJ33: =(IFERROR(AI33/AB33,0)) -> 0.24865668 | AM33: =D33+M33+P33+S33+U33 -> 1964.7 | AO33: 117942.5 | AS33: 117942.5 | AW33: 113000.5 | AX33: 113000.5 | AZ33: 2603 | BD33: 2603 | BG33: 10943 | BH33: 2981 | BM33: 10943 | BN33: 4.2039954 | BO33: =IFERROR(AB33/AS33,0) -> 0.79102359 | BP33: 45.310219
A34: 33 | B34: 撤店 | C34: 深圳万象食家多径 | D34: 0 | E34: 7.5 | F34: 0 | G34: 7.5 | J34: 0 | K34: 0 | Z34: 0 | AB34: =G34+H34+J34+L34+M34+N34+O34+P34+R34+S34+T34+U34+V34+X34+Z34+AA34 -> 7.5 | AC34: 7.455 | AE34: 0 | AF34: 0 | AG34: -1064.25 | AH34: 0 | AI34: -1064.25 | AJ34: =(IFERROR(AI34/AB34,0)) -> -141.9 | AM34: =D34+M34+P34+S34+U34 -> 0 | AN34: 1568.5 | AS34: 1568.5 | AT34: 0 | AX34: 0 | AY34: 45.5 | BD34: 45.5 | BG34: 153 | BH34: 862.5 | BK34: 0 | BL34: 0 | BM34: 153 | BN34: 3.3626374 | BO34: =IFERROR(AB34/AS34,0) -> 0.0047816385 | BP34: 34.472527
A35: 34 | B35: 撤店 | C35: 深圳宝安壹方城figgyfinds | J35: 0 | K35: 0 | AA35: -1287.25 | AB35: =G35+H35+J35+L35+M35+N35+O35+P35+R35+S35+T35+U35+V35+X35+Z35+AA35 -> -1287.25 | AC35: -1287.25 | AE35: 0 | AF35: 0 | AG35: -439.5 | AH35: 0 | AI35: -439.5 | AJ35: =(IFERROR(AI35/AB35,0)) -> 0.34142552 | AM35: =D35+M35+P35+S35+U35 -> 0 | AS35: 0 | AX35: 0 | BD35: 0 | BG35: 56 | BH35: 349 | BM35: 56 | BO35: =IFERROR(AB35/AS35,0) -> 0
A36: 35 | B36: 撤店 | C36: 上海凯德1uone | I36: 106 | J36: 0 | K36: 0 | AB36: =G36+H36+J36+L36+M36+N36+O36+P36+R36+S36+T36+U36+V36+X36+Z36+AA36 -> 0 | AC36: 0 | AE36: 0 | AF36: 0 | AG36: 0 | AH36: 0 | AI36: 0 | AJ36: =(IFERROR(AI36/AB36,0)) -> 0 | AM36: =D36+M36+P36+S36+U36 -> 0 | AS36: 0 | AX36: 0 | BD36: 0 | BM36: 0 | BO36: =IFERROR(AB36/AS36,0) -> 0
A37: 36 | B37: 撤店 | C37: 东方宝泰 | D37: 0 | E37: 0 | F37: 0 | G37: 0 | Z37: -62.975 | AB37: =G37+H37+J37+L37+M37+N37+O37+P37+R37+S37+T37+U37+V37+X37+Z37+AA37 -> -62.975 | AC37: -62.975 | AE37: 0 | AF37: 0 | AG37: 0 | AH37: 0 | AI37: 0 | AJ37: =(IFERROR(AI37/AB37,0)) -> 0 | AM37: =D37+M37+P37+S37+U37 -> 0 | AN37: 0 | AS37: 0 | AT37: 0 | AX37: 0 | AY37: 0 | BD37: 0 | BK37: 0 | BL37: 0 | BM37: 0 | BO37: =IFERROR(AB37/AS37,0) -> 0
A38: 37 | B38: 撤店 | C38: 上海宝山天街店（不支持门店自提） | D38: 0 | E38: 0 | F38: 0 | G38: 0 | Z38: 0 | AB38: =G38+H38+J38+L38+M38+N38+O38+P38+R38+S38+T38+U38+V38+X38+Z38+AA38 -> 0 | AC38: 0 | AE38: 0 | AF38: 0 | AG38: 0 | AH38: 0 | AI38: 0 | AJ38: =(IFERROR(AI38/AB38,0)) -> 0 | AM38: =D38+M38+P38+S38+U38 -> 0 | AN38: 0 | AS38: 0 | AT38: 0 | AX38: 0 | AY38: 0 | BD38: 0 | BK38: 0 | BL38: 0 | BM38: 0 | BO38: =IFERROR(AB38/AS38,0) -> 0
A39: 38 | B39: 撤店 | C39: 上海来福士小鹿的屋（不支持兑换自提） | D39: 0 | E39: 0 | F39: 0 | G39: 0 | Z39: 0 | AB39: =G39+H39+J39+L39+M39+N39+O39+P39+R39+S39+T39+U39+V39+X39+Z39+AA39 -> 0 | AC39: 0 | AE39: 0 | AF39: 0 | AG39: 0 | AH39: 0 | AI39: 0 | AJ39: =(IFERROR(AI39/AB39,0)) -> 0 | AM39: =D39+M39+P39+S39+U39 -> 0 | AN39: 0 | AS39: 0 | AT39: 0 | AX39: 0 | AY39: 0 | BD39: 0 | BK39: 0 | BL39: 0 | BM39: 0 | BO39: =IFERROR(AB39/AS39,0) -> 0
A40: 39 | B40: 撤店 | C40: 广州海珠万达 | D40: 0 | E40: 0 | F40: 0 | G40: 0 | Z40: 0 | AB40: =G40+H40+J40+L40+M40+N40+O40+P40+R40+S40+T40+U40+V40+X40+Z40+AA40 -> 0 | AC40: 0 | AE40: 0 | AF40: 0 | AG40: 0 | AH40: 0 | AI40: 0 | AJ40: =(IFERROR(AI40/AB40,0)) -> 0 | AM40: =D40+M40+P40+S40+U40 -> 0 | AN40: 0 | AS40: 0 | AT40: 0 | AX40: 0 | AY40: 0 | BD40: 0 | BK40: 0 | BL40: 0 | BM40: 0 | BO40: =IFERROR(AB40/AS40,0) -> 0
...

Sheet 小叮当
A1: 序号 | B1: 负责人 | C1: 场地 | D1: 芸苔现金 | E1: 芸苔微信 | F1: 芸苔支付宝 | G1: 芸苔非团购 | H1: 抖音收款 | I1: 抖音手续费 | J1: 美团收款 | K1: 美团手续费 | L1: 乐摇摇收款 | M1: 多金宝现金 | N1: 多金宝非现金 | O1: 汇联非现金 | P1: 汇联现金 | Q1: 汇联手续费 | R1: StarThing非现金 | S1: StarThing现金 | T1: 鲸舰非现金 | U1: 鲸舰现金 | V1: Kpay收款 | W1: Kpay手续费 | X1: 八达通收款 | Y1: 八达通手续费 | Z1: 芸苔远程取币 | AA1: 其他收入 | AB1: 收入汇总 | AC1: 扣除手续费后 | AD1: 基础货款 | AE1: StarThing积分货款 | AF1: 鲸舰积分货款 | AG1: 新系统积分货款 | AH1: 芸苔积分货款 | AI1: 总货款 | AJ1: 货款比% | AK1: 预计收入(万元) | AL1: 预收入完成率 | AM1: 现金 | AN1: 芸苔投币 | AO1: 多金宝投币 | AP1: 乐摇摇投币 | AQ1: StarThing投币 | AR1: 鲸舰投币 | AS1: 投币合计 | AT1: 芸苔出币 | AU1: StarThing出币 | AV1: 鲸舰出币 | AW1: 多金宝出币 | AX1: 出币合计 | AY1: 芸苔出货 | AZ1: 多金宝出货 | BA1: 乐摇摇出货 | BB1: StarThing出货 | BC1: 鲸舰出货 | BD1: 出货合计 | BE1: 鲸舰积分增加 | BF1: 鲸舰积分减少 | BG1: 新系统积分增加 | BH1: 新系统积分减少 | BI1: StarThing积分增加 | BJ1: StarThing积分减少 | BK1: 芸苔积分增加 | BL1: 芸苔积分减少 | BM1: 存货合计 | BN1: 存货比率（存货与出货比） | BO1: 币值（收入与投币比） | BP1: 出货率（投币与出货比）
A2: =_xlfn._xlws.FILTER(Sheet1!A:BL,Sheet1!B:B="小叮当") -> #VALUE!

Sheet 郑伟峰
A1: 序号 | B1: 负责人 | C1: 场地 | D1: 芸苔现金 | E1: 芸苔微信 | F1: 芸苔支付宝 | G1: 芸苔非团购 | H1: 抖音收款 | I1: 抖音手续费 | J1: 美团收款 | K1: 美团手续费 | L1: 乐摇摇收款 | M1: 多金宝现金 | N1: 多金宝非现金 | O1: 汇联非现金 | P1: 汇联现金 | Q1: 汇联手续费 | R1: StarThing非现金 | S1: StarThing现金 | T1: 鲸舰非现金 | U1: 鲸舰现金 | V1: Kpay收款 | W1: Kpay手续费 | X1: 八达通收款 | Y1: 八达通手续费 | Z1: 芸苔远程取币 | AA1: 其他收入 | AB1: 收入汇总 | AC1: 扣除手续费后 | AD1: 基础货款 | AE1: StarThing积分货款 | AF1: 鲸舰积分货款 | AG1: 新系统积分货款 | AH1: 芸苔积分货款 | AI1: 总货款 | AJ1: 货款比% | AK1: 预计收入(万元) | AL1: 预收入完成率 | AM1: 现金 | AN1: 芸苔投币 | AO1: 多金宝投币 | AP1: 乐摇摇投币 | AQ1: StarThing投币 | AR1: 鲸舰投币 | AS1: 投币合计 | AT1: 芸苔出币 | AU1: StarThing出币 | AV1: 鲸舰出币 | AW1: 多金宝出币 | AX1: 出币合计 | AY1: 芸苔出货 | AZ1: 多金宝出货 | BA1: 乐摇摇出货 | BB1: StarThing出货 | BC1: 鲸舰出货 | BD1: 出货合计 | BE1: 鲸舰积分增加 | BF1: 鲸舰积分减少 | BG1: 新系统积分增加 | BH1: 新系统积分减少 | BI1: StarThing积分增加 | BJ1: StarThing积分减少 | BK1: 芸苔积分增加 | BL1: 芸苔积分减少 | BM1: 存货合计 | BN1: 存货比率（存货与出货比） | BO1: 币值（收入与投币比） | BP1: 出货率（投币与出货比）
A2: {=_xlfn._xlws.FILTER(Sheet1!A:BP,Sheet1!B:B="郑伟峰")} -> 2 | B2: 郑伟峰 | C2: 福州东百中心 | D2: 7351.1 | E2: 22088.75 | F2: 3159.65 | G2: 32599.5 | H2: 66864.6 | I2: 3347.345 | J2: 21847.6 | K2: 1094.35 | L2: 3558.95 | M2: 0 | N2: 0 | O2: 0 | P2: 0 | Q2: 0 | R2: 0 | S2: 0 | T2: 0 | U2: 0 | V2: 0 | W2: 0 | X2: 0 | Y2: 0 | Z2: 0 | AA2: 0 | AB2: 124870.65 | AC2: 120256.11 | AD2: -10299.195 | AE2: 0 | AF2: 0 | AG2: -1413.75 | AH2: 0 | AI2: -11712.945 | AJ2: -0.093800625 | AK2: 0 | AL2: 0 | AM2: 7351.1 | AN2: 42703.5 | AO2: 0 | AP2: 161281 | AQ2: 0 | AR2: 0 | AS2: 203984.5 | AT2: 169926 | AU2: 0 | AV2: 0 | AW2: 0 | AX2: 169926 | AY2: 103.5 | AZ2: 0 | BA2: 3557 | BB2: 0 | BC2: 0 | BD2: 3660.5 | BE2: 0 | BF2: 0 | BG2: 4868.5 | BH2: 5811 | BI2: 0 | BJ2: 0 | BK2: 0 | BL2: 0 | BM2: 4868.5 | BN2: 1.3300096 | BO2: 0.61215754 | BP2: 55.725857
A3: 3 | B3: 郑伟峰 | C3: 福州苏宁广场 | D3: 90 | E3: 1459.85 | F3: 260 | G3: 1809.85 | H3: 855.45 | I3: 42.75 | J3: 402 | K3: 20.15 | L3: 0 | M3: 0 | N3: 0 | O3: 0 | P3: 0 | Q3: 0 | R3: 0 | S3: 0 | T3: 0 | U3: 0 | V3: 0 | W3: 0 | X3: 0 | Y3: 0 | Z3: 0 | AA3: 0 | AB3: 3067.3 | AC3: 2994.0809 | AD3: 0 | AE3: 0 | AF3: 0 | AG3: 0 | AH3: 0 | AI3: 0 | AJ3: 0 | AK3: 0 | AL3: 0 | AM3: 90 | AN3: 5412.5 | AO3: 0 | AP3: 0 | AQ3: 0 | AR3: 0 | AS3: 5412.5 | AT3: 3699.5 | AU3: 0 | AV3: 0 | AW3: 0 | AX3: 3699.5 | AY3: 87.5 | AZ3: 0 | BA3: 0 | BB3: 0 | BC3: 0 | BD3: 87.5 | BE3: 0 | BF3: 0 | BG3: 0 | BH3: 0 | BI3: 0 | BJ3: 0 | BK3: 0 | BL3: 0 | BM3: 0 | BN3: 0 | BO3: 0.5667067 | BP3: 61.857143
A4: 4 | B4: 郑伟峰 | C4: 福州苏宁广场solmo | D4: 0 | E4: 0 | F4: 0 | G4: 0 | H4: 46715.8 | I4: 2350.235 | J4: 19334.35 | K4: 1466.94 | L4: 0 | M4: 581.35 | N4: 16288.4 | O4: 0 | P4: 0 | Q4: 0 | R4: 0 | S4: 0 | T4: 0 | U4: 0 | V4: 0 | W4: 0 | X4: 0 | Y4: 0 | Z4: 0 | AA4: 0 | AB4: 82919.9 | AC4: 79004.995 | AD4: 35286.1 | AE4: 0 | AF4: 0 | AG4: 3510 | AH4: 0 | AI4: 38796.1 | AJ4: 0.46787442 | AK4: 0 | AL4: 0 | AM4: 581.35 | AN4: 0 | AO4: 113416 | AP4: 0 | AQ4: 0 | AR4: 0 | AS4: 113416 | AT4: 0 | AU4: 0 | AV4: 0 | AW4: 467904.5 | AX4: 467904.5 | AY4: 0 | AZ4: 2387 | BA4: 0 | BB4: 0 | BC4: 0 | BD4: 2387 | BE4: 0 | BF4: 0 | BG4: 5463 | BH4: 3123 | BI4: 0 | BJ4: 0 | BK4: 0 | BL4: 0 | BM4: 5463 | BN4: 2.2886468 | BO4: 0.73111289 | BP4: 47.514034
A5: 5 | B5: 郑伟峰 | C5: 福州X118多径 | D5: 245 | E5: 4697.85 | F5: 524.9 | G5: 5467.75 | H5: 5075.55 | I5: 253.86 | J5: 1437.2 | K5: 72 | L5: 460.85 | M5: 0 | N5: 0 | O5: 0 | P5: 0 | Q5: 0 | R5: 0 | S5: 0 | T5: 0 | U5: 0 | V5: 0 | W5: 0 | X5: 0 | Y5: 0 | Z5: 0 | AA5: 0 | AB5: 12441.35 | AC5: 12081.388 | AD5: 1052 | AE5: 0 | AF5: 0 | AG5: 0 | AH5: 0 | AI5: 1052 | AJ5: 0.08455674 | AK5: 0 | AL5: 0 | AM5: 245 | AN5: 17466 | AO5: 0 | AP5: 3759.5 | AQ5: 0 | AR5: 0 | AS5: 21225.5 | AT5: 18148.5 | AU5: 0 | AV5: 0 | AW5: 0 | AX5: 18148.5 | AY5: 141 | AZ5: 0 | BA5: 23 | BB5: 0 | BC5: 0 | BD5: 164 | BE5: 0 | BF5: 0 | BG5: 0 | BH5: 0 | BI5: 0 | BJ5: 0 | BK5: 0 | BL5: 0 | BM5: 0 | BN5: 0 | BO5: 0.58615109 | BP5: 129.42378
A6: 6 | B6: 郑伟峰 | C6: 东百中心弹珠机 | D6: 53.5 | E6: 3050.35 | F6: 353.35 | G6: 3457.2 | H6: 0 | I6: 0 | J6: 0 | K6: 0 | L6: 0 | M6: 0 | N6: 0 | O6: 0 | P6: 0 | Q6: 0 | R6: 0 | S6: 0 | T6: 0 | U6: 0 | V6: 0 | W6: 0 | X6: 0 | Y6: 0 | Z6: 0 | AA6: 0 | AB6: 3457.2 | AC6: 3436.7778 | AD6: 40 | AE6: 0 | AF6: 0 | AG6: 2594.25 | AH6: 0 | AI6: 2634.25 | AJ6: 0.76196055 | AK6: 0 | AL6: 0 | AM6: 53.5 | AN6: 0 | AO6: 0 | AP6: 0 | AQ6: 0 | AR6: 0 | AS6: 0 | AT6: 381044.5 | AU6: 0 | AV6: 0 | AW6: 0 | AX6: 381044.5 | AY6: 0 | AZ6: 0 | BA6: 0 | BB6: 0 | BC6: 0 | BD6: 0 | BE6: 0 | BF6: 0 | BG6: 2329 | BH6: 599.5 | BI6: 0 | BJ6: 0 | BK6: 0 | BL6: 0 | BM6: 2329 | BN6: 0 | BO6: 0 | BP6: 0

Sheet 梁志成
A1: 序号 | B1: 负责人 | C1: 场地 | D1: 芸苔现金 | E1: 芸苔微信 | F1: 芸苔支付宝 | G1: 芸苔非团购 | H1: 抖音收款 | I1: 抖音手续费 | J1: 美团收款 | K1: 美团手续费 | L1: 乐摇摇收款 | M1: 多金宝现金 | N1: 多金宝非现金 | O1: 汇联非现金 | P1: 汇联现金 | Q1: 汇联手续费 | R1: StarThing非现金 | S1: StarThing现金 | T1: 鲸舰非现金 | U1: 鲸舰现金 | V1: Kpay收款 | W1: Kpay手续费 | X1: 八达通收款 | Y1: 八达通手续费 | Z1: 芸苔远程取币 | AA1: 其他收入 | AB1: 收入汇总 | AC1: 扣除手续费后 | AD1: 基础货款 | AE1: StarThing积分货款 | AF1: 鲸舰积分货款 | AG1: 新系统积分货款 | AH1: 芸苔积分货款 | AI1: 总货款 | AJ1: 货款比% | AK1: 预计收入(万元) | AL1: 预收入完成率 | AM1: 现金 | AN1: 芸苔投币 | AO1: 多金宝投币 | AP1: 乐摇摇投币 | AQ1: StarThing投币 | AR1: 鲸舰投币 | AS1: 投币合计 | AT1: 芸苔出币 | AU1: StarThing出币 | AV1: 鲸舰出币 | AW1: 多金宝出币 | AX1: 出币合计 | AY1: 芸苔出货 | AZ1: 多金宝出货 | BA1: 乐摇摇出货 | BB1: StarThing出货 | BC1: 鲸舰出货 | BD1: 出货合计 | BE1: 鲸舰积分增加 | BF1: 鲸舰积分减少 | BG1: 新系统积分增加 | BH1: 新系统积分减少 | BI1: StarThing积分增加 | BJ1: StarThing积分减少 | BK1: 芸苔积分增加 | BL1: 芸苔积分减少 | BM1: 存货合计 | BN1: 存货比率（存货与出货比） | BO1: 币值（收入与投币比） | BP1: 出货率（投币与出货比）
A2: {=_xlfn._xlws.FILTER(Sheet1!A:BP,Sheet1!B:B="梁志成")} -> 25 | B2: 梁志成 | C2: 香港宝林FF | D2: 0 | E2: 0 | F2: 0 | G2: 0 | H2: 0 | I2: 0 | J2: 0 | K2: 0 | L2: 0 | M2: 0 | N2: 0 | O2: 0 | P2: 0 | Q2: 0 | R2: 111837.5 | S2: 70945 | T2: 0 | U2: 0 | V2: 0 | W2: 0 | X2: 0 | Y2: 0 | Z2: 0 | AA2: 0 | AB2: 182782.5 | AC2: 182782.5 | AD2: 83532.715 | AE2: 16811 | AF2: 0 | AG2: 0 | AH2: 0 | AI2: 100343.71 | AJ2: 0.54897879 | AK2: 0 | AL2: 0 | AM2: 70945 | AN2: 0 | AO2: 0 | AP2: 0 | AQ2: 0 | AR2: 0 | AS2: 0 | AT2: 0 | AU2: 371008.5 | AV2: 0 | AW2: 0 | AX2: 371008.5 | AY2: 0 | AZ2: 0 | BA2: 0 | BB2: 5049.5 | BC2: 0 | BD2: 5049.5 | BE2: 0 | BF2: 0 | BG2: 0 | BH2: 0 | BI2: 45565.32 | BJ2: 28754.32 | BK2: 0 | BL2: 0 | BM2: 45565.32 | BN2: 9.0237291 | BO2: 0 | BP2: 0
A3: 26 | B3: 梁志成 | C3: 香港将军澳店 | D3: 0 | E3: 0 | F3: 0 | G3: 0 | H3: 0 | I3: 0 | J3: 0 | K3: 0 | L3: 0 | M3: 3568 | N3: 0 | O3: 0 | P3: 0 | Q3: 0 | R3: 4885 | S3: 7345 | T3: 0 | U3: 0 | V3: 18309.5 | W3: 263.65 | X3: 3909.5 | Y3: 0 | Z3: 0 | AA3: 0 | AB3: 38017 | AC3: 37753.35 | AD3: 44957.44 | AE3: 0 | AF3: 0 | AG3: 0 | AH3: 0 | AI3: 44957.44 | AJ3: 1.1825615 | AK3: 0 | AL3: 0 | AM3: 10913 | AN3: 0 | AO3: 37247.5 | AP3: 0 | AQ3: 0 | AR3: 0 | AS3: 37247.5 | AT3: 0 | AU3: 0 | AV3: 0 | AW3: 0 | AX3: 0 | AY3: 0 | AZ3: 1435 | BA3: 0 | BB3: 0 | BC3: 0 | BD3: 1435 | BE3: 0 | BF3: 0 | BG3: 0 | BH3: 0 | BI3: 0 | BJ3: 0 | BK3: 0 | BL3: 0 | BM3: 0 | BN3: 0 | BO3: 1.0206591 | BP3: 25.956446

Sheet 方小丹
A1: 序号 | B1: 负责人 | C1: 场地 | D1: 芸苔现金 | E1: 芸苔微信 | F1: 芸苔支付宝 | G1: 芸苔非团购 | H1: 抖音收款 | I1: 抖音手续费 | J1: 美团收款 | K1: 美团手续费 | L1: 乐摇摇收款 | M1: 多金宝现金 | N1: 多金宝非现金 | O1: 汇联非现金 | P1: 汇联现金 | Q1: 汇联手续费 | R1: StarThing非现金 | S1: StarThing现金 | T1: 鲸舰非现金 | U1: 鲸舰现金 | V1: Kpay收款 | W1: Kpay手续费 | X1: 八达通收款 | Y1: 八达通手续费 | Z1: 芸苔远程取币 | AA1: 其他收入 | AB1: 收入汇总 | AC1: 扣除手续费后 | AD1: 基础货款 | AE1: StarThing积分货款 | AF1: 鲸舰积分货款 | AG1: 新系统积分货款 | AH1: 芸苔积分货款 | AI1: 总货款 | AJ1: 货款比% | AK1: 预计收入(万元) | AL1: 预收入完成率 | AM1: 现金 | AN1: 芸苔投币 | AO1: 多金宝投币 | AP1: 乐摇摇投币 | AQ1: StarThing投币 | AR1: 鲸舰投币 | AS1: 投币合计 | AT1: 芸苔出币 | AU1: StarThing出币 | AV1: 鲸舰出币 | AW1: 多金宝出币 | AX1: 出币合计 | AY1: 芸苔出货 | AZ1: 多金宝出货 | BA1: 乐摇摇出货 | BB1: StarThing出货 | BC1: 鲸舰出货 | BD1: 出货合计 | BE1: 鲸舰积分增加 | BF1: 鲸舰积分减少 | BG1: 新系统积分增加 | BH1: 新系统积分减少 | BI1: StarThing积分增加 | BJ1: StarThing积分减少 | BK1: 芸苔积分增加 | BL1: 芸苔积分减少 | BM1: 存货合计 | BN1: 存货比率（存货与出货比） | BO1: 币值（收入与投币比） | BP1: 出货率（投币与出货比）
A2: {=_xlfn._xlws.FILTER(Sheet1!A:BP,Sheet1!B:B="方小丹")} -> 7 | B2: 方小丹 | C2: 广州悦汇城负一 | D2: 2217.5 | E2: 28043.45 | F2: 5652.75 | G2: 35913.7 | H2: 14.75 | I2: 0.74 | J2: 14355.55 | K2: 719.3 | L2: 0 | M2: 0 | N2: 0 | O2: 0 | P2: 0 | Q2: 0 | R2: 0 | S2: 0 | T2: 0 | U2: 0 | V2: 0 | W2: 0 | X2: 0 | Y2: 0 | Z2: -589.6 | AA2: 0 | AB2: 49694.4 | AC2: 48772.183 | AD2: 12587.79 | AE2: 0 | AF2: 0 | AG2: -756.75 | AH2: 0 | AI2: 11831.04 | AJ2: 0.23807592 | AK2: 0 | AL2: 0 | AM2: 2217.5 | AN2: 99062 | AO2: 0 | AP2: 0 | AQ2: 0 | AR2: 0 | AS2: 99062 | AT2: 88889.5 | AU2: 0 | AV2: 0 | AW2: 0 | AX2: 88889.5 | AY2: 2640 | AZ2: 0 | BA2: 0 | BB2: 0 | BC2: 0 | BD2: 2640 | BE2: 0 | BF2: 0 | BG2: 2319.5 | BH2: 2824 | BI2: 0 | BJ2: 0 | BK2: 0 | BL2: 0 | BM2: 2319.5 | BN2: 0.87859848 | BO2: 0.50164947 | BP2: 37.523485
A3: 8 | B3: 方小丹 | C3: 江门台山万达 | D3: 1626 | E3: 14033.8 | F3: 1835.5 | G3: 17495.3 | H3: 10002 | I3: 508.165 | J3: 6036.3 | K3: 302.44 | L3: 0 | M3: 0 | N3: 0 | O3: 0 | P3: 0 | Q3: 0 | R3: 0 | S3: 0 | T3: 0 | U3: 0 | V3: 0 | W3: 0 | X3: 0 | Y3: 0 | Z3: -67.925 | AA3: 0 | AB3: 33465.675 | AC3: 32559.854 | AD3: 10588.75 | AE3: 0 | AF3: 0 | AG3: 480 | AH3: 0 | AI3: 11068.75 | AJ3: 0.33074934 | AK3: 0 | AL3: 0 | AM3: 1626 | AN3: 62416.5 | AO3: 0 | AP3: 0 | AQ3: 0 | AR3: 0 | AS3: 62416.5 | AT3: 80520.5 | AU3: 0 | AV3: 0 | AW3: 0 | AX3: 80520.5 | AY3: 1845 | AZ3: 0 | BA3: 0 | BB3: 0 | BC3: 0 | BD3: 1845 | BE3: 0 | BF3: 0 | BG3: 1657.5 | BH3: 1337.5 | BI3: 0 | BJ3: 0 | BK3: 0 | BL3: 0 | BM3: 1657.5 | BN3: 0.89837398 | BO3: 0.53616712 | BP3: 33.830081
A4: 9 | B4: 方小丹 | C4: 广州保利时光里 | D4: 3546.3 | E4: 27647.3 | F4: 3075.95 | G4: 34269.55 | H4: 14166.95 | I4: 710.225 | J4: 8825.4 | K4: 442.25 | L4: 0 | M4: 0 | N4: 0 | O4: 0 | P4: 0 | Q4: 0 | R4: 0 | S4: 0 | T4: 0 | U4: 0 | V4: 0 | W4: 0 | X4: 0 | Y4: 0 | Z4: 720.5 | AA4: 0 | AB4: 57982.4 | AC4: 56645.586 | AD4: 16649.55 | AE4: 0 | AF4: 0 | AG4: 0 | AH4: 2414.25 | AI4: 19063.8 | AJ4: 0.32878598 | AK4: 0 | AL4: 0 | AM4: 3546.3 | AN4: 97847.5 | AO4: 0 | AP4: 0 | AQ4: 0 | AR4: 0 | AS4: 97847.5 | AT4: 99388 | AU4: 0 | AV4: 0 | AW4: 0 | AX4: 99388 | AY4: 2932 | AZ4: 0 | BA4: 0 | BB4: 0 | BC4: 0 | BD4: 2932 | BE4: 0 | BF4: 0 | BG4: 0 | BH4: 0 | BI4: 0 | BJ4: 0 | BK4: 6218.5 | BL4: 4609 | BM4: 6218.5 | BN4: 2.1209072 | BO4: 0.59257927 | BP4: 33.372271
A5: 10 | B5: 方小丹 | C5: 广州南沙悦方城 | D5: 0 | E5: 0 | F5: 0 | G5: 0 | H5: 0 | I5: 0 | J5: 0 | K5: 0 | L5: 0 | M5: 0 | N5: 0 | O5: 0 | P5: 0 | Q5: 0 | R5: 0 | S5: 0 | T5: 0 | U5: 0 | V5: 0 | W5: 0 | X5: 0 | Y5: 0 | Z5: 0 | AA5: 0 | AB5: 0 | AC5: 0 | AD5: 0 | AE5: 0 | AF5: 0 | AG5: -192 | AH5: 0 | AI5: -192 | AJ5: 0 | AK5: 0 | AL5: 0 | AM5: 0 | AN5: 0 | AO5: 0 | AP5: 0 | AQ5: 0 | AR5: 0 | AS5: 0 | AT5: 0 | AU5: 0 | AV5: 0 | AW5: 0 | AX5: 0 | AY5: 0 | AZ5: 0 | BA5: 0 | BB5: 0 | BC5: 0 | BD5: 0 | BE5: 0 | BF5: 0 | BG5: 20.5 | BH5: 148.5 | BI5: 0 | BJ5: 0 | BK5: 0 | BL5: 0 | BM5: 20.5 | BN5: 0 | BO5: 0 | BP5: 0
A6: 11 | B6: 方小丹 | C6: 广州南沙悦方城多径 | D6: 0 | E6: 0 | F6: 0 | G6: 0 | H6: 0 | I6: 0 | J6: 0 | K6: 0 | L6: 0 | M6: 0 | N6: 0 | O6: 0 | P6: 0 | Q6: 0 | R6: 0 | S6: 0 | T6: 0 | U6: 0 | V6: 0 | W6: 0 | X6: 0 | Y6: 0 | Z6: 0 | AA6: 0 | AB6: 0 | AC6: 0 | AD6: 0 | AE6: 0 | AF6: 0 | AG6: 0 | AH6: 0 | AI6: 0 | AJ6: 0 | AK6: 0 | AL6: 0 | AM6: 0 | AN6: 0 | AO6: 0 | AP6: 0 | AQ6: 0 | AR6: 0 | AS6: 0 | AT6: 0 | AU6: 0 | AV6: 0 | AW6: 0 | AX6: 0 | AY6: 0 | AZ6: 0 | BA6: 0 | BB6: 0 | BC6: 0 | BD6: 0 | BE6: 0 | BF6: 0 | BG6: 0 | BH6: 0 | BI6: 0 | BJ6: 0 | BK6: 0 | BL6: 0 | BM6: 0 | BN6: 0 | BO6: 0 | BP6: 0
A7: 12 | B7: 方小丹 | C7: 健康港星河(广州星河多径) | D7: 233.5 | E7: 2892.45 | F7: 348.15 | G7: 3474.1 | H7: 0 | I7: 0 | J7: 0 | K7: 0 | L7: 44.85 | M7: 0 | N7: 0 | O7: 0 | P7: 0 | Q7: 0 | R7: 0 | S7: 0 | T7: 0 | U7: 0 | V7: 0 | W7: 0 | X7: 0 | Y7: 0 | Z7: 0 | AA7: 0 | AB7: 3518.95 | AC7: 3499.2373 | AD7: 0 | AE7: 0 | AF7: 0 | AG7: 0 | AH7: 0 | AI7: 0 | AJ7: 0 | AK7: 0 | AL7: 0 | AM7: 233.5 | AN7: 2865.5 | AO7: 0 | AP7: 3333 | AQ7: 0 | AR7: 0 | AS7: 6198.5 | AT7: 5870.5 | AU7: 0 | AV7: 0 | AW7: 0 | AX7: 5870.5 | AY7: 107 | AZ7: 0 | BA7: 145.5 | BB7: 0 | BC7: 0 | BD7: 252.5 | BE7: 0 | BF7: 0 | BG7: 0 | BH7: 0 | BI7: 0 | BJ7: 0 | BK7: 0 | BL7: 0 | BM7: 0 | BN7: 0 | BO7: 0.56770993 | BP7: 24.548515
A8: 13 | B8: 方小丹 | C8: 深圳宝安怀德万象汇solmo | D8: 0 | E8: 0 | F8: 0 | G8: 0 | H8: 8183.6 | I8: 411.21 | J8: 4868.1 | K8: 350.53 | L8: 0 | M8: 798 | N8: 12964.6 | O8: 0 | P8: 0 | Q8: 0 | R8: 0 | S8: 0 | T8: 0 | U8: 0 | V8: 0 | W8: 0 | X8: 0 | Y8: 0 | Z8: 0 | AA8: 64.23 | AB8: 26878.53 | AC8: 26039.002 | AD8: 9869.525 | AE8: 0 | AF8: 0 | AG8: -605.25 | AH8: 0 | AI8: 9264.275 | AJ8: 0.34467194 | AK8: 0 | AL8: 0 | AM8: 798 | AN8: 0 | AO8: 60258 | AP8: 0 | AQ8: 0 | AR8: 0 | AS8: 60258 | AT8: 0 | AU8: 0 | AV8: 0 | AW8: 111309.5 | AX8: 111309.5 | AY8: 0 | AZ8: 2499.5 | BA8: 0 | BB8: 0 | BC8: 0 | BD8: 2499.5 | BE8: 0 | BF8: 0 | BG8: 329 | BH8: 732.5 | BI8: 0 | BJ8: 0 | BK8: 0 | BL8: 0 | BM8: 329 | BN8: 0.13162633 | BO8: 0.44605745 | BP8: 24.108022
A9: 14 | B9: 方小丹 | C9: 深圳宝安怀德万象汇figgyfinds | D9: 0 | E9: 0 | F9: 0 | G9: 0 | H9: 890.15 | I9: 45.28 | J9: 0 | K9: 0 | L9: 0 | M9: 117.5 | N9: 1775.65 | O9: 0 | P9: 0 | Q9: 0 | R9: 0 | S9: 0 | T9: 0 | U9: 0 | V9: 0 | W9: 0 | X9: 0 | Y9: 0 | Z9: 0 | AA9: 11.23 | AB9: 2794.53 | AC9: 2738.5961 | AD9: 446.645 | AE9: 0 | AF9: 0 | AG9: -156.75 | AH9: 0 | AI9: 289.895 | AJ9: 0.10373659 | AK9: 0 | AL9: 0 | AM9: 117.5 | AN9: 0 | AO9: 997.5 | AP9: 13.5 | AQ9: 0 | AR9: 0 | AS9: 1011 | AT9: 0 | AU9: 0 | AV9: 0 | AW9: 17203 | AX9: 17203 | AY9: 0 | AZ9: 11.5 | BA9: 0.5 | BB9: 0 | BC9: 0 | BD9: 12 | BE9: 0 | BF9: 0 | BG9: 0 | BH9: 104.5 | BI9: 0 | BJ9: 0 | BK9: 0 | BL9: 0 | BM9: 0 | BN9: 0 | BO9: 2.7641246 | BP9: 84.25
A10: 15 | B10: 方小丹 | C10: 深圳龙岗大运天地figgyfinds | D10: 0 | E10: 0 | F10: 0 | G10: 0 | H10: 38723.45 | I10: 1943.64 | J10: 20011.2 | K10: 1276.135 | L10: 0 | M10: 1463.4 | N10: 20643 | O10: 0 | P10: 0 | Q10: 0 | R10: 0 | S10: 0 | T10: 0 | U10: 0 | V10: 0 | W10: 0 | X10: 0 | Y10: 0 | Z10: 0 | AA10: 411.72 | AB10: 81252.77 | AC10: 77909.137 | AD10: 22911.235 | AE10: 0 | AF10: 0 | AG10: -5130 | AH10: 0 | AI10: 17781.235 | AJ10: 0.21883851 | AK10: 0 | AL10: 0 | AM10: 1463.4 | AN10: 0 | AO10: 91854 | AP10: 0 | AQ10: 0 | AR10: 0 | AS10: 91854 | AT10: 0 | AU10: 0 | AV10: 0 | AW10: 365546 | AX10: 365546 | AY10: 0 | AZ10: 2028 | BA10: 0 | BB10: 0 | BC10: 0 | BD10: 2028 | BE10: 0 | BF10: 0 | BG10: 6783.5 | BH10: 10203.5 | BI10: 0 | BJ10: 0 | BK10: 0 | BL10: 0 | BM10: 6783.5 | BN10: 3.3449211 | BO10: 0.88458608 | BP10: 45.292899
A11: 16 | B11: 方小丹 | C11: 深圳海岸城爪物超柿 | D11: 0 | E11: 0 | F11: 0 | G11: 0 | H11: 29449.205 | I11: 1486.46 | J11: 54848.35 | K11: 3501.825 | L11: 0 | M11: 1908.55 | N11: 68561.2 | O11: 0 | P11: 0 | Q11: 0 | R11: 0 | S11: 0 | T11: 0 | U11: 0 | V11: 0 | W11: 0 | X11: 0 | Y11: 0 | Z11: 0 | AA11: 0 | AB11: 154767.3 | AC11: 149367.65 | AD11: 90509.685 | AE11: 0 | AF11: 0 | AG11: 21251.25 | AH11: 0 | AI11: 111760.93 | AJ11: 0.72212238 | AK11: 0 | AL11: 0 | AM11: 1908.55 | AN11: 0 | AO11: 302312 | AP11: 0 | AQ11: 0 | AR11: 0 | AS11: 302312 | AT11: 0 | AU11: 0 | AV11: 0 | AW11: 365424.5 | AX11: 365424.5 | AY11: 0 | AZ11: 6102 | BA11: 0 | BB11: 0 | BC11: 0 | BD11: 6102 | BE11: 0 | BF11: 0 | BG11: 16426.5 | BH11: 2259 | BI11: 0 | BJ11: 0 | BK11: 0 | BL11: 0 | BM11: 16426.5 | BN11: 2.6919862 | BO11: 0.51194562 | BP11: 49.543101
A12: 17 | B12: 方小丹 | C12: 深圳布吉万象汇figgyfinds | D12: 0 | E12: 0 | F12: 0 | G12: 0 | H12: 46630.35 | I12: 2346.89 | J12: 33972.05 | K12: 1509.66 | L12: 0 | M12: 2113.2 | N12: 35279.75 | O12: 0 | P12: 0 | Q12: 0 | R12: 0 | S12: 0 | T12: 0 | U12: 0 | V12: 0 | W12: 0 | X12: 0 | Y12: 0 | Z12: 0 | AA12: 500 | AB12: 118495.35 | AC12: 114427.12 | AD12: 45770.345 | AE12: 0 | AF12: 0 | AG12: -69 | AH12: 0 | AI12: 45701.345 | AJ12: 0.38568049 | AK12: 0 | AL12: 0 | AM12: 2113.2 | AN12: 0 | AO12: 231439.5 | AP12: 0 | AQ12: 0 | AR12: 0 | AS12: 231439.5 | AT12: 0 | AU12: 0 | AV12: 0 | AW12: 250575 | AX12: 250575 | AY12: 0 | AZ12: 4615 | BA12: 0 | BB12: 0 | BC12: 0 | BD12: 4615 | BE12: 0 | BF12: 0 | BG12: 18928.5 | BH12: 18974.5 | BI12: 0 | BJ12: 0 | BK12: 0 | BL12: 0 | BM12: 18928.5 | BN12: 4.1015168 | BO12: 0.51199277 | BP12: 50.149404
A13: 18 | B13: 方小丹 | C13: 广州花都骏壹万邦广场figgyfinds | D13: 0 | E13: 0 | F13: 0 | G13: 0 | H13: 36282.31 | I13: 1824.89 | J13: 38994.4 | K13: 2479.605 | L13: 0 | M13: 2082 | N13: 43626.35 | O13: 0 | P13: 0 | Q13: 0 | R13: 0 | S13: 0 | T13: 0 | U13: 0 | V13: 0 | W13: 0 | X13: 0 | Y13: 0 | Z13: 0 | AA13: 0 | AB13: 120985.06 | AC13: 116418.81 | AD13: 41771.655 | AE13: 0 | AF13: 0 | AG13: 1126.5 | AH13: 0 | AI13: 42898.155 | AJ13: 0.35457399 | AK13: 0 | AL13: 0 | AM13: 2082 | AN13: 0 | AO13: 211258 | AP13: 0 | AQ13: 0 | AR13: 0 | AS13: 211258 | AT13: 0 | AU13: 0 | AV13: 0 | AW13: 198348 | AX13: 198348 | AY13: 0 | AZ13: 4307 | BA13: 0 | BB13: 0 | BC13: 0 | BD13: 4307 | BE13: 0 | BF13: 0 | BG13: 14741.5 | BH13: 13990.5 | BI13: 0 | BJ13: 0 | BK13: 0 | BL13: 0 | BM13: 14741.5 | BN13: 3.422684 | BO13: 0.57268866 | BP13: 49.049919
A14: 19 | B14: 方小丹 | C14: 东莞松山湖万象汇figgyfinds | D14: 0 | E14: 0 | F14: 0 | G14: 0 | H14: 66939 | I14: 3368.2 | J14: 32865.9 | K14: 2271.475 | L14: 0 | M14: 1069.55 | N14: 29009.5 | O14: 0 | P14: 0 | Q14: 0 | R14: 0 | S14: 0 | T14: 0 | U14: 0 | V14: 0 | W14: 0 | X14: 0 | Y14: 0 | Z14: 0 | AA14: 10.88 | AB14: 129894.83 | AC14: 124081.1 | AD14: 46664.255 | AE14: 0 | AF14: 0 | AG14: -3476.25 | AH14: 0 | AI14: 43188.005 | AJ14: 0.3324844 | AK14: 0 | AL14: 0 | AM14: 1069.55 | AN14: 0 | AO14: 186151 | AP14: 0 | AQ14: 0 | AR14: 0 | AS14: 186151 | AT14: 0 | AU14: 0 | AV14: 0 | AW14: 533912 | AX14: 533912 | AY14: 0 | AZ14: 4463.5 | BA14: 0 | BB14: 0 | BC14: 0 | BD14: 4463.5 | BE14: 0 | BF14: 0 | BG14: 12225.5 | BH14: 14543 | BI14: 0 | BJ14: 0 | BK14: 0 | BL14: 0 | BM14: 12225.5 | BN14: 2.7389941 | BO14: 0.69779281 | BP14: 41.705164
... A16: 21 | B16: 方小丹 | C16: Solmo娃娃市集(摩尔城店) | D16: 0 | E16: 0 | F16: 0 | G16: 0 | H16: 3601.6 | I16: 180.855 | J16: 2557.5 | K16: 182.71 | L16: 0 | M16: 754 | N16: 6583.2 | O16: 0 | P16: 0 | Q16: 0 | R16: 0 | S16: 0 | T16: 0 | U16: 0 | V16: 0 | W16: 0 | X16: 0 | Y16: 0 | Z16: 0 | AA16: 0 | AB16: 13496.3 | AC16: 13093.236 | AD16: 50 | AE16: 0 | AF16: 0 | AG16: 0 | AH16: 0 | AI16: 50 | AJ16: 0.0037047191 | AK16: 0 | AL16: 0 | AM16: 754 | AN16: 0 | AO16: 0 | AP16: 0 | AQ16: 0 | AR16: 0 | AS16: 0 | AT16: 0 | AU16: 0 | AV16: 0 | AW16: 134897.5 | AX16: 134897.5 | AY16: 0 | AZ16: 0 | BA16: 0 | BB16: 0 | BC16: 0 | BD16: 0 | BE16: 0 | BF16: 0 | BG16: 0 | BH16: 0 | BI16: 0 | BJ16: 0 | BK16: 0 | BL16: 0 | BM16: 0 | BN16: 0 | BO16: 0 | BP16: 0

Sheet 洪奕翔
A1: 序号 | B1: 负责人 | C1: 场地 | D1: 芸苔现金 | E1: 芸苔微信 | F1: 芸苔支付宝 | G1: 芸苔非团购 | H1: 抖音收款 | I1: 抖音手续费 | J1: 美团收款 | K1: 美团手续费 | L1: 乐摇摇收款 | M1: 多金宝现金 | N1: 多金宝非现金 | O1: 汇联非现金 | P1: 汇联现金 | Q1: 汇联手续费 | R1: StarThing非现金 | S1: StarThing现金 | T1: 鲸舰非现金 | U1: 鲸舰现金 | V1: Kpay收款 | W1: Kpay手续费 | X1: 八达通收款 | Y1: 八达通手续费 | Z1: 芸苔远程取币 | AA1: 其他收入 | AB1: 收入汇总 | AC1: 扣除手续费后 | AD1: 基础货款 | AE1: StarThing积分货款 | AF1: 鲸舰积分货款 | AG1: 新系统积分货款 | AH1: 芸苔积分货款 | AI1: 总货款 | AJ1: 货款比% | AK1: 预计收入(万元) | AL1: 预收入完成率 | AM1: 现金 | AN1: 芸苔投币 | AO1: 多金宝投币 | AP1: 乐摇摇投币 | AQ1: StarThing投币 | AR1: 鲸舰投币 | AS1: 投币合计 | AT1: 芸苔出币 | AU1: StarThing出币 | AV1: 鲸舰出币 | AW1: 多金宝出币 | AX1: 出币合计 | AY1: 芸苔出货 | AZ1: 多金宝出货 | BA1: 乐摇摇出货 | BB1: StarThing出货 | BC1: 鲸舰出货 | BD1: 出货合计 | BE1: 鲸舰积分增加 | BF1: 鲸舰积分减少 | BG1: 新系统积分增加 | BH1: 新系统积分减少 | BI1: StarThing积分增加 | BJ1: StarThing积分减少 | BK1: 芸苔积分增加 | BL1: 芸苔积分减少 | BM1: 存货合计 | BN1: 存货比率（存货与出货比） | BO1: 币值（收入与投币比） | BP1: 出货率（投币与出货比）
A2: {=_xlfn._xlws.FILTER(Sheet1!A:BP,Sheet1!B:B="洪奕翔")} -> 1 | B2: 洪奕翔 | C2: 深圳皇庭广场figgyfinds | D2: 0 | E2: 0 | F2: 0 | G2: 0 | H2: 32618.9 | I2: 1670.37 | J2: 48559 | K2: 2455.52 | L2: 0 | M2: 5344.8 | N2: 146906.83 | O2: 0 | P2: 0 | Q2: 0 | R2: 0 | S2: 0 | T2: 0 | U2: 0 | V2: 0 | W2: 0 | X2: 0 | Y2: 0 | Z2: 0 | AA2: 0 | AB2: 233429.53 | AC2: 228422.19 | AD2: 79099.065 | AE2: 0 | AF2: 0 | AG2: -73754.25 | AH2: 0 | AI2: 5344.815 | AJ2: 0.022896911 | AK2: 0 | AL2: 0 | AM2: 5344.8 | AN2: 0 | AO2: 426866.5 | AP2: 0 | AQ2: 0 | AR2: 0 | AS2: 426866.5 | AT2: 0 | AU2: 0 | AV2: 0 | AW2: 510203.5 | AX2: 510203.5 | AY2: 0 | AZ2: 4691 | BA2: 0 | BB2: 0 | BC2: 0 | BD2: 4691 | BE2: 0 | BF2: 0 | BG2: 44235.5 | BH2: 93405 | BI2: 0 | BJ2: 0 | BK2: 0 | BL2: 0 | BM2: 44235.5 | BN2: 9.4298657 | BO2: 0.54684433 | BP2: 90.996909

Sheet 吴兴涛
A1: 序号 | B1: 负责人 | C1: 场地 | D1: 芸苔现金 | E1: 芸苔微信 | F1: 芸苔支付宝 | G1: 芸苔非团购 | H1: 抖音收款 | I1: 抖音手续费 | J1: 美团收款 | K1: 美团手续费 | L1: 乐摇摇收款 | M1: 多金宝现金 | N1: 多金宝非现金 | O1: 汇联非现金 | P1: 汇联现金 | Q1: 汇联手续费 | R1: StarThing非现金 | S1: StarThing现金 | T1: 鲸舰非现金 | U1: 鲸舰现金 | V1: Kpay收款 | W1: Kpay手续费 | X1: 八达通收款 | Y1: 八达通手续费 | Z1: 芸苔远程取币 | AA1: 其他收入 | AB1: 收入汇总 | AC1: 扣除手续费后 | AD1: 基础货款 | AE1: StarThing积分货款 | AF1: 鲸舰积分货款 | AG1: 新系统积分货款 | AH1: 芸苔积分货款 | AI1: 总货款 | AJ1: 货款比% | AK1: 预计收入(万元) | AL1: 预收入完成率 | AM1: 现金 | AN1: 芸苔投币 | AO1: 多金宝投币 | AP1: 乐摇摇投币 | AQ1: StarThing投币 | AR1: 鲸舰投币 | AS1: 投币合计 | AT1: 芸苔出币 | AU1: StarThing出币 | AV1: 鲸舰出币 | AW1: 多金宝出币 | AX1: 出币合计 | AY1: 芸苔出货 | AZ1: 多金宝出货 | BA1: 乐摇摇出货 | BB1: StarThing出货 | BC1: 鲸舰出货 | BD1: 出货合计 | BE1: 鲸舰积分增加 | BF1: 鲸舰积分减少 | BG1: 新系统积分增加 | BH1: 新系统积分减少 | BI1: StarThing积分增加 | BJ1: StarThing积分减少 | BK1: 芸苔积分增加 | BL1: 芸苔积分减少 | BM1: 存货合计 | BN1: 存货比率（存货与出货比） | BO1: 币值（收入与投币比） | BP1: 出货率（投币与出货比）
A2: {=_xlfn._xlws.FILTER(Sheet1!A:BP,Sheet1!B:B="吴兴涛")} -> 27 | B2: 吴兴涛 | C2: 香港K11 | D2: 0 | E2: 0 | F2: 0 | G2: 0 | H2: 0 | I2: 0 | J2: 0 | K2: 0 | L2: 0 | M2: 0 | N2: 0 | O2: 0 | P2: 0 | Q2: 0 | R2: 0 | S2: 0 | T2: 38650 | U2: 332049.5 | V2: 0 | W2: 0 | X2: 0 | Y2: 0 | Z2: 0 | AA2: 0 | AB2: 370699.5 | AC2: 370699.5 | AD2: 287886.92 | AE2: 0 | AF2: 58234.5 | AG2: 0 | AH2: 0 | AI2: 346121.42 | AJ2: 0.9336981 | AK2: 0 | AL2: 0 | AM2: 332049.5 | AN2: 0 | AO2: 0 | AP2: 0 | AQ2: 0 | AR2: 544396 | AS2: 544396 | AT2: 0 | AU2: 0 | AV2: 454091 | AW2: 0 | AX2: 454091 | AY2: 0 | AZ2: 0 | BA2: 0 | BB2: 0 | BC2: 13124 | BD2: 13124 | BE2: 140615.5 | BF2: 82381 | BG2: 0 | BH2: 0 | BI2: 0 | BJ2: 0 | BK2: 0 | BL2: 0 | BM2: 140615.5 | BN2: 10.714378 | BO2: 0.68093722 | BP2: 41.480951

Sheet 文龙
A1: 序号 | B1: 负责人 | C1: 场地 | D1: 芸苔现金 | E1: 芸苔微信 | F1: 芸苔支付宝 | G1: 芸苔非团购 | H1: 抖音收款 | I1: 抖音手续费 | J1: 美团收款 | K1: 美团手续费 | L1: 乐摇摇收款 | M1: 多金宝现金 | N1: 多金宝非现金 | O1: 汇联非现金 | P1: 汇联现金 | Q1: 汇联手续费 | R1: StarThing非现金 | S1: StarThing现金 | T1: 鲸舰非现金 | U1: 鲸舰现金 | V1: Kpay收款 | W1: Kpay手续费 | X1: 八达通收款 | Y1: 八达通手续费 | Z1: 芸苔远程取币 | AA1: 其他收入 | AB1: 收入汇总 | AC1: 扣除手续费后 | AD1: 基础货款 | AE1: StarThing积分货款 | AF1: 鲸舰积分货款 | AG1: 新系统积分货款 | AH1: 芸苔积分货款 | AI1: 总货款 | AJ1: 货款比% | AK1: 预计收入(万元) | AL1: 预收入完成率 | AM1: 现金 | AN1: 芸苔投币 | AO1: 多金宝投币 | AP1: 乐摇摇投币 | AQ1: StarThing投币 | AR1: 鲸舰投币 | AS1: 投币合计 | AT1: 芸苔出币 | AU1: StarThing出币 | AV1: 鲸舰出币 | AW1: 多金宝出币 | AX1: 出币合计 | AY1: 芸苔出货 | AZ1: 多金宝出货 | BA1: 乐摇摇出货 | BB1: StarThing出货 | BC1: 鲸舰出货 | BD1: 出货合计 | BE1: 鲸舰积分增加 | BF1: 鲸舰积分减少 | BG1: 新系统积分增加 | BH1: 新系统积分减少 | BI1: StarThing积分增加 | BJ1: StarThing积分减少 | BK1: 芸苔积分增加 | BL1: 芸苔积分减少 | BM1: 存货合计 | BN1: 存货比率（存货与出货比） | BO1: 币值（收入与投币比） | BP1: 出货率（投币与出货比）
A2: {=_xlfn._xlws.FILTER(Sheet1!A:BP,Sheet1!B:B="文龙")} -> 28 | B2: 文龙 | C2: 香港沙田希尔顿物超柿 | D2: 0 | E2: 0 | F2: 0 | G2: 0 | H2: 0 | I2: 0 | J2: 0 | K2: 0 | L2: 0 | M2: 0 | N2: 0 | O2: 0 | P2: 0 | Q2: 0 | R2: 0 | S2: 0 | T2: 125841.5 | U2: 63241 | V2: 0 | W2: 0 | X2: 0 | Y2: 0 | Z2: 0 | AA2: 0 | AB2: 189082.5 | AC2: 189082.5 | AD2: 117431.43 | AE2: 0 | AF2: -49642 | AG2: 0 | AH2: 0 | AI2: 67789.43 | AJ2: 0.35851774 | AK2: 0 | AL2: 0 | AM2: 63241 | AN2: 0 | AO2: 0 | AP2: 0 | AQ2: 0 | AR2: 275411.5 | AS2: 275411.5 | AT2: 0 | AU2: 0 | AV2: 260465 | AW2: 0 | AX2: 260465 | AY2: 0 | AZ2: 0 | BA2: 0 | BB2: 0 | BC2: 5083 | BD2: 5083 | BE2: 60113 | BF2: 109755 | BG2: 0 | BH2: 0 | BI2: 0 | BJ2: 0 | BK2: 0 | BL2: 0 | BM2: 60113 | BN2: 11.826284 | BO2: 0.68654541 | BP2: 54.182864

Sheet 王青
A1: 序号 | B1: 负责人 | C1: 场地 | D1: 芸苔现金 | E1: 芸苔微信 | F1: 芸苔支付宝 | G1: 芸苔非团购 | H1: 抖音收款 | I1: 抖音手续费 | J1: 美团收款 | K1: 美团手续费 | L1: 乐摇摇收款 | M1: 多金宝现金 | N1: 多金宝非现金 | O1: 汇联非现金 | P1: 汇联现金 | Q1: 汇联手续费 | R1: StarThing非现金 | S1: StarThing现金 | T1: 鲸舰非现金 | U1: 鲸舰现金 | V1: Kpay收款 | W1: Kpay手续费 | X1: 八达通收款 | Y1: 八达通手续费 | Z1: 芸苔远程取币 | AA1: 其他收入 | AB1: 收入汇总 | AC1: 扣除手续费后 | AD1: 基础货款 | AE1: StarThing积分货款 | AF1: 鲸舰积分货款 | AG1: 新系统积分货款 | AH1: 芸苔积分货款 | AI1: 总货款 | AJ1: 货款比% | AK1: 预计收入(万元) | AL1: 预收入完成率 | AM1: 现金 | AN1: 芸苔投币 | AO1: 多金宝投币 | AP1: 乐摇摇投币 | AQ1: StarThing投币 | AR1: 鲸舰投币 | AS1: 投币合计 | AT1: 芸苔出币 | AU1: StarThing出币 | AV1: 鲸舰出币 | AW1: 多金宝出币 | AX1: 出币合计 | AY1: 芸苔出货 | AZ1: 多金宝出货 | BA1: 乐摇摇出货 | BB1: StarThing出货 | BC1: 鲸舰出货 | BD1: 出货合计 | BE1: 鲸舰积分增加 | BF1: 鲸舰积分减少 | BG1: 新系统积分增加 | BH1: 新系统积分减少 | BI1: StarThing积分增加 | BJ1: StarThing积分减少 | BK1: 芸苔积分增加 | BL1: 芸苔积分减少 | BM1: 存货合计 | BN1: 存货比率（存货与出货比） | BO1: 币值（收入与投币比） | BP1: 出货率（投币与出货比）
A2: {=_xlfn._xlws.FILTER(Sheet1!A:BP,Sheet1!B:B="王青")} -> 22 | B2: 王青 | C2: 上海宏伊广场 | D2: 5147.35 | E2: 24437.35 | F2: 21668.3 | G2: 51253 | H2: 9923.25 | I2: 501.08 | J2: 8020.45 | K2: 401.8 | L2: 0 | M2: 0 | N2: 0 | O2: 0 | P2: 0 | Q2: 0 | R2: 0 | S2: 0 | T2: 0 | U2: 0 | V2: 0 | W2: 0 | X2: 0 | Y2: 0 | Z2: 0 | AA2: 0 | AB2: 69196.7 | AC2: 68017.186 | AD2: 0 | AE2: 0 | AF2: 0 | AG2: -113.25 | AH2: 0 | AI2: -113.25 | AJ2: -0.0016366387 | AK2: 0 | AL2: 0 | AM2: 5147.35 | AN2: 76076.5 | AO2: 0 | AP2: 0 | AQ2: 0 | AR2: 0 | AS2: 76076.5 | AT2: 73204.5 | AU2: 0 | AV2: 0 | AW2: 0 | AX2: 73204.5 | AY2: 2147.5 | AZ2: 0 | BA2: 0 | BB2: 0 | BC2: 0 | BD2: 2147.5 | BE2: 0 | BF2: 0 | BG2: 1461 | BH2: 1536.5 | BI2: 0 | BJ2: 0 | BK2: 0 | BL2: 0 | BM2: 1461 | BN2: 0.68032596 | BO2: 0.90956734 | BP2: 35.425611
A3: 23 | B3: 王青 | C3: 香港黄埔物超柿 | D3: 0 | E3: 0 | F3: 0 | G3: 0 | H3: 0 | I3: 0 | J3: 0 | K3: 0 | L3: 0 | M3: 0 | N3: 0 | O3: 0 | P3: 0 | Q3: 0 | R3: 0 | S3: 0 | T3: 146998.8 | U3: 314654.8 | V3: 0 | W3: 0 | X3: 0 | Y3: 0 | Z3: 0 | AA3: 0 | AB3: 461653.6 | AC3: 461653.6 | AD3: 190487.38 | AE3: 0 | AF3: 34425.5 | AG3: 0 | AH3: 0 | AI3: 224912.88 | AJ3: 0.48718969 | AK3: 0 | AL3: 0 | AM3: 314654.8 | AN3: 0 | AO3: 0 | AP3: 0 | AQ3: 0 | AR3: 607582.5 | AS3: 607582.5 | AT3: 0 | AU3: 0 | AV3: 598338.5 | AW3: 0 | AX3: 598338.5 | AY3: 0 | AZ3: 0 | BA3: 0 | BB3: 0 | BC3: 14943.5 | BD3: 14943.5 | BE3: 74443.5 | BF3: 40018 | BG3: 0 | BH3: 0 | BI3: 0 | BJ3: 0 | BK3: 0 | BL3: 0 | BM3: 74443.5 | BN3: 4.9816643 | BO3: 0.75982044 | BP3: 40.658648
A4: 24 | B4: 王青 | C4: 香港九龙城店 | D4: 0 | E4: 0 | F4: 0 | G4: 0 | H4: 0 | I4: 0 | J4: 0 | K4: 0 | L4: 0 | M4: 400 | N4: 0 | O4: 0 | P4: 0 | Q4: 0 | R4: 0 | S4: 0 | T4: 0 | U4: 0 | V4: 294.5 | W4: 5.24 | X4: 0 | Y4: 0 | Z4: 0 | AA4: 14945 | AB4: 15639.5 | AC4: 15634.26 | AD4: -9001 | AE4: 0 | AF4: 0 | AG4: 0 | AH4: 0 | AI4: -9001 | AJ4: -0.57552991 | AK4: 0 | AL4: 0 | AM4: 400 | AN4: 0 | AO4: 199.5 | AP4: 0 | AQ4: 0 | AR4: 0 | AS4: 199.5 | AT4: 0 | AU4: 0 | AV4: 0 | AW4: 0 | AX4: 0 | AY4: 0 | AZ4: 3 | BA4: 0 | BB4: 0 | BC4: 0 | BD4: 3 | BE4: 0 | BF4: 0 | BG4: 0 | BH4: 0 | BI4: 0 | BJ4: 0 | BK4: 0 | BL4: 0 | BM4: 0 | BN4: 0 | BO4: 78.393484 | BP4: 66.5
C5: 106

Sheet 徐丹
A1: 序号 | B1: 负责人 | C1: 场地 | D1: 芸苔现金 | E1: 芸苔微信 | F1: 芸苔支付宝 | G1: 芸苔非团购 | H1: 抖音收款 | I1: 抖音手续费 | J1: 美团收款 | K1: 美团手续费 | L1: 乐摇摇收款 | M1: 多金宝现金 | N1: 多金宝非现金 | O1: 汇联非现金 | P1: 汇联现金 | Q1: 汇联手续费 | R1: StarThing非现金 | S1: StarThing现金 | T1: 鲸舰非现金 | U1: 鲸舰现金 | V1: Kpay收款 | W1: Kpay手续费 | X1: 八达通收款 | Y1: 八达通手续费 | Z1: 芸苔远程取币 | AA1: 其他收入 | AB1: 收入汇总 | AC1: 扣除手续费后 | AD1: 基础货款 | AE1: StarThing积分货款 | AF1: 鲸舰积分货款 | AG1: 新系统积分货款 | AH1: 芸苔积分货款 | AI1: 总货款 | AJ1: 货款比% | AK1: 预计收入(万元) | AL1: 预收入完成率 | AM1: 现金 | AN1: 芸苔投币 | AO1: 多金宝投币 | AP1: 乐摇摇投币 | AQ1: StarThing投币 | AR1: 鲸舰投币 | AS1: 投币合计 | AT1: 芸苔出币 | AU1: StarThing出币 | AV1: 鲸舰出币 | AW1: 多金宝出币 | AX1: 出币合计 | AY1: 芸苔出货 | AZ1: 多金宝出货 | BA1: 乐摇摇出货 | BB1: StarThing出货 | BC1: 鲸舰出货 | BD1: 出货合计 | BE1: 鲸舰积分增加 | BF1: 鲸舰积分减少 | BG1: 新系统积分增加 | BH1: 新系统积分减少 | BI1: StarThing积分增加 | BJ1: StarThing积分减少 | BK1: 芸苔积分增加 | BL1: 芸苔积分减少 | BM1: 存货合计 | BN1: 存货比率（存货与出货比） | BO1: 币值（收入与投币比） | BP1: 出货率（投币与出货比）
A2: {=_xlfn._xlws.FILTER(Sheet1!A:BP,Sheet1!B:B="徐丹")} -> 29 | B2: 徐丹 | C2: 香港如心物超柿 | D2: 0 | E2: 0 | F2: 0 | G2: 0 | H2: 0 | I2: 0 | J2: 0 | K2: 0 | L2: 0 | M2: 0 | N2: 0 | O2: 0 | P2: 0 | Q2: 0 | R2: 38859 | S2: 29746.5 | T2: 0 | U2: 0 | V2: 0 | W2: 0 | X2: 0 | Y2: 0 | Z2: 0 | AA2: 0 | AB2: 68605.5 | AC2: 68605.5 | AD2: 9377.75 | AE2: 1537.5 | AF2: 0 | AG2: 0 | AH2: 0 | AI2: 10915.25 | AJ2: 0.15910168 | AK2: 0 | AL2: 0 | AM2: 29746.5 | AN2: 0 | AO2: 0 | AP2: 0 | AQ2: 0 | AR2: 0 | AS2: 0 | AT2: 0 | AU2: 79453 | AV2: 0 | AW2: 0 | AX2: 79453 | AY2: 0 | AZ2: 0 | BA2: 0 | BB2: 1692.5 | BC2: 0 | BD2: 1692.5 | BE2: 0 | BF2: 0 | BG2: 0 | BH2: 0 | BI2: 13304.5 | BJ2: 11767 | BK2: 0 | BL2: 0 | BM2: 13304.5 | BN2: 7.8608567 | BO2: 0 | BP2: 0
A3: 30 | B3: 徐丹 | C3: 香港荃湾FF | D3: 0 | E3: 0 | F3: 0 | G3: 0 | H3: 0 | I3: 0 | J3: 0 | K3: 0 | L3: 0 | M3: 0 | N3: 0 | O3: 0 | P3: 0 | Q3: 0 | R3: 0 | S3: 0 | T3: 100899.45 | U3: 67393.5 | V3: 0 | W3: 0 | X3: 106 | Y3: 0 | Z3: 0 | AA3: 0 | AB3: 168292.95 | AC3: 168292.95 | AD3: 142508.02 | AE3: 0 | AF3: -23491.5 | AG3: 0 | AH3: 0 | AI3: 119016.52 | AJ3: 0.70719849 | AK3: 0 | AL3: 0 | AM3: 67393.5 | AN3: 0 | AO3: 0 | AP3: 0 | AQ3: 0 | AR3: 274303 | AS3: 274303 | AT3: 0 | AU3: 0 | AV3: 199626.5 | AW3: 0 | AX3: 199626.5 | AY3: 0 | AZ3: 0 | BA3: 0 | BB3: 0 | BC3: 9402 | BD3: 9402 | BE3: 112229.5 | BF3: 135721 | BG3: 0 | BH3: 0 | BI3: 0 | BJ3: 0 | BK3: 0 | BL3: 0 | BM3: 112229.5 | BN3: 11.936769 | BO3: 0.61352938 | BP3: 29.174963
A4: 31 | B4: 徐丹 | C4: 香港大学物超柿 | D4: 0 | E4: 0 | F4: 0 | G4: 0 | H4: 0 | I4: 0 | J4: 0 | K4: 0 | L4: 0 | M4: 0 | N4: 0 | O4: 0 | P4: 0 | Q4: 0 | R4: 0 | S4: 0 | T4: 3268.5 | U4: 8432 | V4: 0 | W4: 0 | X4: 0 | Y4: 0 | Z4: 0 | AA4: 0 | AB4: 11700.5 | AC4: 11700.5 | AD4: 17228.275 | AE4: 0 | AF4: -10868 | AG4: 0 | AH4: 0 | AI4: 6360.275 | AJ4: 0.54359002 | AK4: 0 | AL4: 0 | AM4: 8432 | AN4: 0 | AO4: 0 | AP4: 0 | AQ4: 0 | AR4: 14412 | AS4: 14412 | AT4: 0 | AU4: 0 | AV4: 10715 | AW4: 0 | AX4: 10715 | AY4: 0 | AZ4: 0 | BA4: 0 | BB4: 0 | BC4: 180.5 | BD4: 180.5 | BE4: 1335.5 | BF4: 12203.5 | BG4: 0 | BH4: 0 | BI4: 0 | BJ4: 0 | BK4: 0 | BL4: 0 | BM4: 1335.5 | BN4: 7.398892 | BO4: 0.81185817 | BP4: 79.844875
A5: 32 | B5: 徐丹 | C5: Figgy Finds娃娃市集(罗湖店) | D5: 0 | E5: 0 | F5: 0 | G5: 0 | H5: 31215.45 | I5: 1587.685 | J5: 19749.35 | K5: 1358.915 | L5: 0 | M5: 1964.7 | N5: 40365.8 | O5: 0 | P5: 0 | Q5: 0 | R5: 0 | S5: 0 | T5: 0 | U5: 0 | V5: 0 | W5: 0 | X5: 0 | Y5: 0 | Z5: 0 | AA5: 0 | AB5: 93295.3 | AC5: 90106.505 | AD5: 11255.5 | AE5: 0 | AF5: 0 | AG5: 11943 | AH5: 0 | AI5: 23198.5 | AJ5: 0.24865668 | AK5: 0 | AL5: 0 | AM5: 1964.7 | AN5: 0 | AO5: 117942.5 | AP5: 0 | AQ5: 0 | AR5: 0 | AS5: 117942.5 | AT5: 0 | AU5: 0 | AV5: 0 | AW5: 113000.5 | AX5: 113000.5 | AY5: 0 | AZ5: 2603 | BA5: 0 | BB5: 0 | BC5: 0 | BD5: 2603 | BE5: 0 | BF5: 0 | BG5: 10943 | BH5: 2981 | BI5: 0 | BJ5: 0 | BK5: 0 | BL5: 0 | BM5: 10943 | BN5: 4.2039954 | BO5: 0.79102359 | BP5: 45.310219

Sheet 撤店
A1: 序号 | B1: 负责人 | C1: 场地 | D1: 芸苔现金 | E1: 芸苔微信 | F1: 芸苔支付宝 | G1: 芸苔非团购 | H1: 抖音收款 | I1: 抖音手续费 | J1: 美团收款 | K1: 美团手续费 | L1: 乐摇摇收款 | M1: 多金宝现金 | N1: 多金宝非现金 | O1: 汇联非现金 | P1: 汇联现金 | Q1: 汇联手续费 | R1: StarThing非现金 | S1: StarThing现金 | T1: 鲸舰非现金 | U1: 鲸舰现金 | V1: Kpay收款 | W1: Kpay手续费 | X1: 八达通收款 | Y1: 八达通手续费 | Z1: 芸苔远程取币 | AA1: 其他收入 | AB1: 收入汇总 | AC1: 扣除手续费后 | AD1: 基础货款 | AE1: StarThing积分货款 | AF1: 鲸舰积分货款 | AG1: 新系统积分货款 | AH1: 芸苔积分货款 | AI1: 总货款 | AJ1: 货款比% | AK1: 预计收入(万元) | AL1: 预收入完成率 | AM1: 现金 | AN1: 芸苔投币 | AO1: 多金宝投币 | AP1: 乐摇摇投币 | AQ1: StarThing投币 | AR1: 鲸舰投币 | AS1: 投币合计 | AT1: 芸苔出币 | AU1: StarThing出币 | AV1: 鲸舰出币 | AW1: 多金宝出币 | AX1: 出币合计 | AY1: 芸苔出货 | AZ1: 多金宝出货 | BA1: 乐摇摇出货 | BB1: StarThing出货 | BC1: 鲸舰出货 | BD1: 出货合计 | BE1: 鲸舰积分增加 | BF1: 鲸舰积分减少 | BG1: 新系统积分增加 | BH1: 新系统积分减少 | BI1: StarThing积分增加 | BJ1: StarThing积分减少 | BK1: 芸苔积分增加 | BL1: 芸苔积分减少 | BM1: 存货合计 | BN1: 存货比率（存货与出货比） | BO1: 币值（收入与投币比） | BP1: 出货率（投币与出货比）
A2: {=_xlfn._xlws.FILTER(Sheet1!A:BP,Sheet1!B:B="撤店")} -> 33 | B2: 撤店 | C2: 深圳万象食家多径 | D2: 0 | E2: 7.5 | F2: 0 | G2: 7.5 | H2: 0 | I2: 0 | J2: 0 | K2: 0 | L2: 0 | M2: 0 | N2: 0 | O2: 0 | P2: 0 | Q2: 0 | R2: 0 | S2: 0 | T2: 0 | U2: 0 | V2: 0 | W2: 0 | X2: 0 | Y2: 0 | Z2: 0 | AA2: 0 | AB2: 7.5 | AC2: 7.455 | AD2: 0 | AE2: 0 | AF2: 0 | AG2: -1064.25 | AH2: 0 | AI2: -1064.25 | AJ2: -141.9 | AK2: 0 | AL2: 0 | AM2: 0 | AN2: 1568.5 | AO2: 0 | AP2: 0 | AQ2: 0 | AR2: 0 | AS2: 1568.5 | AT2: 0 | AU2: 0 | AV2: 0 | AW2: 0 | AX2: 0 | AY2: 45.5 | AZ2: 0 | BA2: 0 | BB2: 0 | BC2: 0 | BD2: 45.5 | BE2: 0 | BF2: 0 | BG2: 153 | BH2: 862.5 | BI2: 0 | BJ2: 0 | BK2: 0 | BL2: 0 | BM2: 153 | BN2: 3.3626374 | BO2: 0.0047816385 | BP2: 34.472527
A3: 34 | B3: 撤店 | C3: 深圳宝安壹方城figgyfinds | D3: 0 | E3: 0 | F3: 0 | G3: 0 | H3: 0 | I3: 0 | J3: 0 | K3: 0 | L3: 0 | M3: 0 | N3: 0 | O3: 0 | P3: 0 | Q3: 0 | R3: 0 | S3: 0 | T3: 0 | U3: 0 | V3: 0 | W3: 0 | X3: 0 | Y3: 0 | Z3: 0 | AA3: -1287.25 | AB3: -1287.25 | AC3: -1287.25 | AD3: 0 | AE3: 0 | AF3: 0 | AG3: -439.5 | AH3: 0 | AI3: -439.5 | AJ3: 0.34142552 | AK3: 0 | AL3: 0 | AM3: 0 | AN3: 0 | AO3: 0 | AP3: 0 | AQ3: 0 | AR3: 0 | AS3: 0 | AT3: 0 | AU3: 0 | AV3: 0 | AW3: 0 | AX3: 0 | AY3: 0 | AZ3: 0 | BA3: 0 | BB3: 0 | BC3: 0 | BD3: 0 | BE3: 0 | BF3: 0 | BG3: 56 | BH3: 349 | BI3: 0 | BJ3: 0 | BK3: 0 | BL3: 0 | BM3: 56 | BN3: 0 | BO3: 0 | BP3: 0
A4: 35 | B4: 撤店 | C4: 上海凯德1uone | D4: 0 | E4: 0 | F4: 0 | G4: 0 | H4: 0 | I4: 106 | J4: 0 | K4: 0 | L4: 0 | M4: 0 | N4: 0 | O4: 0 | P4: 0 | Q4: 0 | R4: 0 | S4: 0 | T4: 0 | U4: 0 | V4: 0 | W4: 0 | X4: 0 | Y4: 0 | Z4: 0 | AA4: 0 | AB4: 0 | AC4: 0 | AD4: 0 | AE4: 0 | AF4: 0 | AG4: 0 | AH4: 0 | AI4: 0 | AJ4: 0 | AK4: 0 | AL4: 0 | AM4: 0 | AN4: 0 | AO4: 0 | AP4: 0 | AQ4: 0 | AR4: 0 | AS4: 0 | AT4: 0 | AU4: 0 | AV4: 0 | AW4: 0 | AX4: 0 | AY4: 0 | AZ4: 0 | BA4: 0 | BB4: 0 | BC4: 0 | BD4: 0 | BE4: 0 | BF4: 0 | BG4: 0 | BH4: 0 | BI4: 0 | BJ4: 0 | BK4: 0 | BL4: 0 | BM4: 0 | BN4: 0 | BO4: 0 | BP4: 0
A5: 36 | B5: 撤店 | C5: 东方宝泰 | D5: 0 | E5: 0 | F5: 0 | G5: 0 | H5: 0 | I5: 0 | J5: 0 | K5: 0 | L5: 0 | M5: 0 | N5: 0 | O5: 0 | P5: 0 | Q5: 0 | R5: 0 | S5: 0 | T5: 0 | U5: 0 | V5: 0 | W5: 0 | X5: 0 | Y5: 0 | Z5: -62.975 | AA5: 0 | AB5: -62.975 | AC5: -62.975 | AD5: 0 | AE5: 0 | AF5: 0 | AG5: 0 | AH5: 0 | AI5: 0 | AJ5: 0 | AK5: 0 | AL5: 0 | AM5: 0 | AN5: 0 | AO5: 0 | AP5: 0 | AQ5: 0 | AR5: 0 | AS5: 0 | AT5: 0 | AU5: 0 | AV5: 0 | AW5: 0 | AX5: 0 | AY5: 0 | AZ5: 0 | BA5: 0 | BB5: 0 | BC5: 0 | BD5: 0 | BE5: 0 | BF5: 0 | BG5: 0 | BH5: 0 | BI5: 0 | BJ5: 0 | BK5: 0 | BL5: 0 | BM5: 0 | BN5: 0 | BO5: 0 | BP5: 0
A6: 37 | B6: 撤店 | C6: 上海宝山天街店（不支持门店自提） | D6: 0 | E6: 0 | F6: 0 | G6: 0 | H6: 0 | I6: 0 | J6: 0 | K6: 0 | L6: 0 | M6: 0 | N6: 0 | O6: 0 | P6: 0 | Q6: 0 | R6: 0 | S6: 0 | T6: 0 | U6: 0 | V6: 0 | W6: 0 | X6: 0 | Y6: 0 | Z6: 0 | AA6: 0 | AB6: 0 | AC6: 0 | AD6: 0 | AE6: 0 | AF6: 0 | AG6: 0 | AH6: 0 | AI6: 0 | AJ6: 0 | AK6: 0 | AL6: 0 | AM6: 0 | AN6: 0 | AO6: 0 | AP6: 0 | AQ6: 0 | AR6: 0 | AS6: 0 | AT6: 0 | AU6: 0 | AV6: 0 | AW6: 0 | AX6: 0 | AY6: 0 | AZ6: 0 | BA6: 0 | BB6: 0 | BC6: 0 | BD6: 0 | BE6: 0 | BF6: 0 | BG6: 0 | BH6: 0 | BI6: 0 | BJ6: 0 | BK6: 0 | BL6: 0 | BM6: 0 | BN6: 0 | BO6: 0 | BP6: 0
A7: 38 | B7: 撤店 | C7: 上海来福士小鹿的屋（不支持兑换自提） | D7: 0 | E7: 0 | F7: 0 | G7: 0 | H7: 0 | I7: 0 | J7: 0 | K7: 0 | L7: 0 | M7: 0 | N7: 0 | O7: 0 | P7: 0 | Q7: 0 | R7: 0 | S7: 0 | T7: 0 | U7: 0 | V7: 0 | W7: 0 | X7: 0 | Y7: 0 | Z7: 0 | AA7: 0 | AB7: 0 | AC7: 0 | AD7: 0 | AE7: 0 | AF7: 0 | AG7: 0 | AH7: 0 | AI7: 0 | AJ7: 0 | AK7: 0 | AL7: 0 | AM7: 0 | AN7: 0 | AO7: 0 | AP7: 0 | AQ7: 0 | AR7: 0 | AS7: 0 | AT7: 0 | AU7: 0 | AV7: 0 | AW7: 0 | AX7: 0 | AY7: 0 | AZ7: 0 | BA7: 0 | BB7: 0 | BC7: 0 | BD7: 0 | BE7: 0 | BF7: 0 | BG7: 0 | BH7: 0 | BI7: 0 | BJ7: 0 | BK7: 0 | BL7: 0 | BM7: 0 | BN7: 0 | BO7: 0 | BP7: 0
A8: 39 | B8: 撤店 | C8: 广州海珠万达 | D8: 0 | E8: 0 | F8: 0 | G8: 0 | H8: 0 | I8: 0 | J8: 0 | K8: 0 | L8: 0 | M8: 0 | N8: 0 | O8: 0 | P8: 0 | Q8: 0 | R8: 0 | S8: 0 | T8: 0 | U8: 0 | V8: 0 | W8: 0 | X8: 0 | Y8: 0 | Z8: 0 | AA8: 0 | AB8: 0 | AC8: 0 | AD8: 0 | AE8: 0 | AF8: 0 | AG8: 0 | AH8: 0 | AI8: 0 | AJ8: 0 | AK8: 0 | AL8: 0 | AM8: 0 | AN8: 0 | AO8: 0 | AP8: 0 | AQ8: 0 | AR8: 0 | AS8: 0 | AT8: 0 | AU8: 0 | AV8: 0 | AW8: 0 | AX8: 0 | AY8: 0 | AZ8: 0 | BA8: 0 | BB8: 0 | BC8: 0 | BD8: 0 | BE8: 0 | BF8: 0 | BG8: 0 | BH8: 0 | BI8: 0 | BJ8: 0 | BK8: 0 | BL8: 0 | BM8: 0 | BN8: 0 | BO8: 0 | BP8: 0
A9: 40 | B9: 撤店 | C9: 广州融创茂（小鹿的屋） | D9: 0 | E9: 0 | F9: 0 | G9: 0 | H9: 0 | I9: 0 | J9: 0 | K9: 0 | L9: 0 | M9: 0 | N9: 0 | O9: 0 | P9: 0 | Q9: 0 | R9: 0 | S9: 0 | T9: 0 | U9: 0 | V9: 0 | W9: 0 | X9: 0 | Y9: 0 | Z9: 0 | AA9: 0 | AB9: 0 | AC9: 0 | AD9: 0 | AE9: 0 | AF9: 0 | AG9: 0 | AH9: 0 | AI9: 0 | AJ9: 0 | AK9: 0 | AL9: 0 | AM9: 0 | AN9: 0 | AO9: 0 | AP9: 0 | AQ9: 0 | AR9: 0 | AS9: 0 | AT9: 0 | AU9: 0 | AV9: 0 | AW9: 0 | AX9: 0 | AY9: 0 | AZ9: 0 | BA9: 0 | BB9: 0 | BC9: 0 | BD9: 0 | BE9: 0 | BF9: 0 | BG9: 0 | BH9: 0 | BI9: 0 | BJ9: 0 | BK9: 0 | BL9: 0 | BM9: 0 | BN9: 0 | BO9: 0 | BP9: 0
